Workbook

Sheet Lucario
A1: 0 | B1: 0 | C1: 0 | D1: 0 | E1: 0 | F1: 0 | G1: 0 | H1: 0 | I1: 0 | J1: 1 | K1: 0 | L1: 0 | M1: 0 | N1: 0 | O1: 0 | P1: 0 | Q1: 0 | R1: 1 | S1: 0 | T1: 0 | U1: 0 | V1: 0 | W1: 0 | X1: 0 | Y1: 0 | Z1: 0 | AA1: 0 | AB1: 0 | AC1: 0 | AD1: 0 | AE1: 0 | AF1: 0 | AG1: 0 | AH1: 0 | AI1: 0 | AJ1: 0
A2: 0 | B2: 0 | C2: 0 | D2: 0 | E2: 0 | F2: 0 | G2: 0 | H2: 0 | I2: 1 | J2: 2 | K2: 1 | L2: 0 | M2: 0 | N2: 0 | O2: 0 | P2: 0 | Q2: 1 | R2: 3 | S2: 1 | T2: 0 | U2: 0 | V2: 0 | W2: 0 | X2: 0 | Y2: 0 | Z2: 0 | AA2: 0 | AB2: 0 | AC2: 0 | AD2: 0 | AE2: 0 | AF2: 0 | AG2: 0 | AH2: 0 | AI2: 0 | AJ2: 0
A3: 0 | B3: 0 | C3: 0 | D3: 0 | E3: 0 | F3: 0 | G3: 0 | H3: 0 | I3: 1 | J3: 2 | K3: 2 | L3: 1 | M3: 0 | N3: 0 | O3: 0 | P3: 0 | Q3: 1 | R3: 3 | S3: 1 | T3: 0 | U3: 0 | V3: 0 | W3: 0 | X3: 0 | Y3: 0 | Z3: 0 | AA3: 0 | AB3: 0 | AC3: 0 | AD3: 0 | AE3: 0 | AF3: 0 | AG3: 0 | AH3: 0 | AI3: 0 | AJ3: 0
A4: 0 | B4: 0 | C4: 0 | D4: 0 | E4: 0 | F4: 0 | G4: 0 | H4: 0 | I4: 1 | J4: 2 | K4: 2 | L4: 1 | M4: 0 | N4: 0 | O4: 0 | P4: 1 | Q4: 3 | R4: 3 | S4: 1 | T4: 0 | U4: 0 | V4: 0 | W4: 0 | X4: 0 | Y4: 0 | Z4: 0 | AA4: 0 | AB4: 0 | AC4: 0 | AD4: 0 | AE4: 0 | AF4: 0 | AG4: 0 | AH4: 0 | AI4: 0 | AJ4: 0
A5: 0 | B5: 0 | C5: 0 | D5: 0 | E5: 0 | F5: 0 | G5: 0 | H5: 0 | I5: 1 | J5: 4 | K5: 2 | L5: 2 | M5: 1 | N5: 0 | O5: 0 | P5: 1 | Q5: 3 | R5: 3 | S5: 3 | T5: 1 | U5: 0 | V5: 0 | W5: 0 | X5: 0 | Y5: 0 | Z5: 0 | AA5: 0 | AB5: 0 | AC5: 0 | AD5: 0 | AE5: 0 | AF5: 0 | AG5: 0 | AH5: 0 | AI5: 0 | AJ5: 0
A6: 0 | B6: 0 | C6: 0 | D6: 0 | E6: 0 | F6: 0 | G6: 0 | H6: 0 | I6: 1 | J6: 4 | K6: 4 | L6: 2 | M6: 1 | N6: 0 | O6: 1 | P6: 3 | Q6: 4 | R6: 3 | S6: 3 | T6: 1 | U6: 0 | V6: 0 | W6: 0 | X6: 0 | Y6: 0 | Z6: 0 | AA6: 0 | AB6: 0 | AC6: 0 | AD6: 0 | AE6: 0 | AF6: 0 | AG6: 0 | AH6: 0 | AI6: 0 | AJ6: 0
A7: 0 | B7: 0 | C7: 0 | D7: 0 | E7: 0 | F7: 0 | G7: 0 | H7: 0 | I7: 0 | J7: 1 | K7: 4 | L7: 2 | M7: 2 | N7: 1 | O7: 4 | P7: 3 | Q7: 4 | R7: 5 | S7: 3 | T7: 1 | U7: 0 | V7: 0 | W7: 0 | X7: 0 | Y7: 0 | Z7: 0 | AA7: 0 | AB7: 0 | AC7: 0 | AD7: 0 | AE7: 0 | AF7: 0 | AG7: 0 | AH7: 0 | AI7: 0 | AJ7: 0
A8: 0 | B8: 0 | C8: 0 | D8: 0 | E8: 0 | F8: 0 | G8: 0 | H8: 0 | I8: 0 | J8: 1 | K8: 4 | L8: 4 | M8: 4 | N8: 5 | O8: 5 | P8: 3 | Q8: 4 | R8: 4 | S8: 3 | T8: 1 | U8: 0 | V8: 0 | W8: 0 | X8: 0 | Y8: 0 | Z8: 0 | AA8: 0 | AB8: 0 | AC8: 0 | AD8: 0 | AE8: 0 | AF8: 0 | AG8: 0 | AH8: 0 | AI8: 0 | AJ8: 0
A9: 0 | B9: 0 | C9: 0 | D9: 0 | E9: 0 | F9: 0 | G9: 0 | H9: 0 | I9: 0 | J9: 0 | K9: 1 | L9: 3 | M9: 5 | N9: 5 | O9: 3 | P9: 4 | Q9: 5 | R9: 4 | S9: 3 | T9: 3 | U9: 1 | V9: 0 | W9: 0 | X9: 0 | Y9: 0 | Z9: 0 | AA9: 0 | AB9: 0 | AC9: 0 | AD9: 0 | AE9: 0 | AF9: 0 | AG9: 0 | AH9: 0 | AI9: 0 | AJ9: 0
A10: 0 | B10: 0 | C10: 0 | D10: 0 | E10: 0 | F10: 0 | G10: 0 | H10: 0 | I10: 0 | J10: 1 | K10: 3 | L10: 5 | M10: 5 | N10: 5 | O10: 3 | P10: 3 | Q10: 3 | R10: 4 | S10: 3 | T10: 2 | U10: 4 | V10: 1 | W10: 0 | X10: 0 | Y10: 0 | Z10: 0 | AA10: 0 | AB10: 0 | AC10: 0 | AD10: 0 | AE10: 0 | AF10: 0 | AG10: 0 | AH10: 0 | AI10: 0 | AJ10: 0
A11: 0 | B11: 0 | C11: 0 | D11: 0 | E11: 0 | F11: 0 | G11: 0 | H11: 0 | I11: 1 | J11: 3 | K11: 3 | L11: 5 | M11: 5 | N11: 3 | O11: 3 | P11: 3 | Q11: 3 | R11: 3 | S11: 5 | T11: 5 | U11: 4 | V11: 4 | W11: 1 | X11: 0 | Y11: 0 | Z11: 0 | AA11: 0 | AB11: 0 | AC11: 0 | AD11: 0 | AE11: 0 | AF11: 0 | AG11: 0 | AH11: 0 | AI11: 0 | AJ11: 0
A12: 0 | B12: 0 | C12: 0 | D12: 0 | E12: 0 | F12: 0 | G12: 0 | H12: 0 | I12: 1 | J12: 3 | K12: 3 | L12: 5 | M12: 5 | N12: 3 | O12: 3 | P12: 3 | Q12: 4 | R12: 4 | S12: 5 | T12: 5 | U12: 5 | V12: 4 | W12: 5 | X12: 1 | Y12: 0 | Z12: 0 | AA12: 0 | AB12: 0 | AC12: 0 | AD12: 0 | AE12: 0 | AF12: 0 | AG12: 0 | AH12: 0 | AI12: 0 | AJ12: 0
... A36: 0 | B36: 0 | C36: 0 | D36: 0 | E36: 0 | F36: 0 | G36: 0 | H36: 0 | I36: 0 | J36: 0 | K36: 0 | L36: 0 | M36: 0 | N36: 0 | O36: 0 | P36: 0 | Q36: 0 | R36: 0 | S36: 0 | T36: 1 | U36: 1 | V36: 1 | W36: 1 | X36: 0 | Y36: 0 | Z36: 0 | AA36: 0 | AB36: 0 | AC36: 0 | AD36: 0 | AE36: 0 | AF36: 0 | AG36: 0 | AH36: 0 | AI36: 0 | AJ36: 0

Sheet transpuestaA
A1: {=TRANSPOSE(Lucario!A1:AK36)} -> 0 | B1: 0 | C1: 0 | D1: 0 | E1: 0 | F1: 0 | G1: 0 | H1: 0 | I1: 0 | J1: 0 | K1: 0 | L1: 0 | M1: 0 | N1: 0 | O1: 0 | P1: 0 | Q1: 0 | R1: 0 | S1: 0 | T1: 0 | U1: 0 | V1: 0 | W1: 0 | X1: 0 | Y1: 0 | Z1: 0 | AA1: 0 | AB1: 0 | AC1: 0 | AD1: 0 | AE1: 0 | AF1: 0 | AG1: 0 | AH1: 0 | AI1: 0 | AJ1: 0
A2: 0 | B2: 0 | C2: 0 | D2: 0 | E2: 0 | F2: 0 | G2: 0 | H2: 0 | I2: 0 | J2: 0 | K2: 0 | L2: 0 | M2: 0 | N2: 0 | O2: 0 | P2: 0 | Q2: 0 | R2: 0 | S2: 0 | T2: 0 | U2: 0 | V2: 0 | W2: 0 | X2: 0 | Y2: 0 | Z2: 0 | AA2: 0 | AB2: 0 | AC2: 0 | AD2: 0 | AE2: 0 | AF2: 0 | AG2: 0 | AH2: 0 | AI2: 0 | AJ2: 0
A3: 0 | B3: 0 | C3: 0 | D3: 0 | E3: 0 | F3: 0 | G3: 0 | H3: 0 | I3: 0 | J3: 0 | K3: 0 | L3: 0 | M3: 0 | N3: 0 | O3: 0 | P3: 0 | Q3: 0 | R3: 0 | S3: 0 | T3: 0 | U3: 0 | V3: 0 | W3: 0 | X3: 0 | Y3: 0 | Z3: 0 | AA3: 0 | AB3: 0 | AC3: 0 | AD3: 0 | AE3: 0 | AF3: 0 | AG3: 0 | AH3: 0 | AI3: 0 | AJ3: 0
A4: 0 | B4: 0 | C4: 0 | D4: 0 | E4: 0 | F4: 0 | G4: 0 | H4: 0 | I4: 0 | J4: 0 | K4: 0 | L4: 0 | M4: 0 | N4: 0 | O4: 0 | P4: 0 | Q4: 0 | R4: 0 | S4: 0 | T4: 0 | U4: 0 | V4: 0 | W4: 0 | X4: 0 | Y4: 0 | Z4: 0 | AA4: 0 | AB4: 0 | AC4: 0 | AD4: 0 | AE4: 0 | AF4: 0 | AG4: 0 | AH4: 0 | AI4: 0 | AJ4: 0
A5: 0 | B5: 0 | C5: 0 | D5: 0 | E5: 0 | F5: 0 | G5: 0 | H5: 0 | I5: 0 | J5: 0 | K5: 0 | L5: 0 | M5: 0 | N5: 0 | O5: 0 | P5: 0 | Q5: 0 | R5: 0 | S5: 0 | T5: 0 | U5: 0 | V5: 0 | W5: 0 | X5: 0 | Y5: 0 | Z5: 0 | AA5: 0 | AB5: 0 | AC5: 0 | AD5: 0 | AE5: 0 | AF5: 0 | AG5: 0 | AH5: 0 | AI5: 0 | AJ5: 0
A6: 0 | B6: 0 | C6: 0 | D6: 0 | E6: 0 | F6: 0 | G6: 0 | H6: 0 | I6: 0 | J6: 0 | K6: 0 | L6: 0 | M6: 0 | N6: 0 | O6: 0 | P6: 0 | Q6: 0 | R6: 0 | S6: 0 | T6: 0 | U6: 0 | V6: 0 | W6: 0 | X6: 0 | Y6: 0 | Z6: 1 | AA6: 0 | AB6: 0 | AC6: 0 | AD6: 0 | AE6: 0 | AF6: 0 | AG6: 0 | AH6: 0 | AI6: 0 | AJ6: 0
A7: 0 | B7: 0 | C7: 0 | D7: 0 | E7: 0 | F7: 0 | G7: 0 | H7: 0 | I7: 0 | J7: 0 | K7: 0 | L7: 0 | M7: 0 | N7: 0 | O7: 0 | P7: 0 | Q7: 0 | R7: 0 | S7: 0 | T7: 0 | U7: 0 | V7: 0 | W7: 0 | X7: 0 | Y7: 1 | Z7: 6 | AA7: 1 | AB7: 1 | AC7: 0 | AD7: 0 | AE7: 0 | AF7: 0 | AG7: 0 | AH7: 0 | AI7: 0 | AJ7: 0
A8: 0 | B8: 0 | C8: 0 | D8: 0 | E8: 0 | F8: 0 | G8: 0 | H8: 0 | I8: 0 | J8: 0 | K8: 0 | L8: 0 | M8: 0 | N8: 0 | O8: 0 | P8: 0 | Q8: 0 | R8: 0 | S8: 0 | T8: 0 | U8: 0 | V8: 0 | W8: 0 | X8: 0 | Y8: 1 | Z8: 6 | AA8: 6 | AB8: 4 | AC8: 1 | AD8: 0 | AE8: 0 | AF8: 0 | AG8: 1 | AH8: 0 | AI8: 0 | AJ8: 0
A9: 0 | B9: 1 | C9: 1 | D9: 1 | E9: 1 | F9: 1 | G9: 0 | H9: 0 | I9: 0 | J9: 0 | K9: 1 | L9: 1 | M9: 1 | N9: 0 | O9: 0 | P9: 1 | Q9: 1 | R9: 0 | S9: 0 | T9: 0 | U9: 0 | V9: 0 | W9: 0 | X9: 1 | Y9: 5 | Z9: 6 | AA9: 4 | AB9: 5 | AC9: 1 | AD9: 0 | AE9: 0 | AF9: 1 | AG9: 5 | AH9: 1 | AI9: 0 | AJ9: 0
A10: 1 | B10: 2 | C10: 2 | D10: 2 | E10: 4 | F10: 4 | G10: 1 | H10: 1 | I10: 0 | J10: 1 | K10: 3 | L10: 3 | M10: 5 | N10: 1 | O10: 1 | P10: 5 | Q10: 4 | R10: 1 | S10: 0 | T10: 0 | U10: 0 | V10: 0 | W10: 1 | X10: 5 | Y10: 5 | Z10: 5 | AA10: 5 | AB10: 4 | AC10: 4 | AD10: 1 | AE10: 0 | AF10: 1 | AG10: 4 | AH10: 1 | AI10: 0 | AJ10: 0
A11: 0 | B11: 1 | C11: 2 | D11: 2 | E11: 2 | F11: 4 | G11: 4 | H11: 4 | I11: 1 | J11: 3 | K11: 3 | L11: 3 | M11: 3 | N11: 5 | O11: 4 | P11: 5 | Q11: 5 | R11: 1 | S11: 0 | T11: 0 | U11: 1 | V11: 1 | W11: 2 | X11: 5 | Y11: 5 | Z11: 4 | AA11: 4 | AB11: 2 | AC11: 4 | AD11: 5 | AE11: 1 | AF11: 5 | AG11: 5 | AH11: 1 | AI11: 0 | AJ11: 0
A12: 0 | B12: 0 | C12: 1 | D12: 1 | E12: 2 | F12: 2 | G12: 2 | H12: 4 | I12: 3 | J12: 5 | K12: 5 | L12: 5 | M12: 5 | N12: 5 | O12: 5 | P12: 5 | Q12: 5 | R12: 1 | S12: 0 | T12: 1 | U12: 2 | V12: 4 | W12: 2 | X12: 2 | Y12: 4 | Z12: 2 | AA12: 2 | AB12: 2 | AC12: 2 | AD12: 4 | AE12: 5 | AF12: 5 | AG12: 5 | AH12: 1 | AI12: 0 | AJ12: 0
A13: 0 | B13: 0 | C13: 0 | D13: 0 | E13: 1 | F13: 1 | G13: 2 | H13: 4 | I13: 5 | J13: 5 | K13: 5 | L13: 5 | M13: 5 | N13: 5 | O13: 5 | P13: 5 | Q13: 5 | R13: 3 | S13: 1 | T13: 5 | U13: 4 | V13: 6 | W13: 4 | X13: 4 | Y13: 5 | Z13: 2 | AA13: 2 | AB13: 2 | AC13: 2 | AD13: 4 | AE13: 1 | AF13: 5 | AG13: 1 | AH13: 0 | AI13: 0 | AJ13: 0
... A37: 0 | B37: 0 | C37: 0 | D37: 0 | E37: 0 | F37: 0 | G37: 0 | H37: 0 | I37: 0 | J37: 0 | K37: 0 | L37: 0 | M37: 0 | N37: 0 | O37: 0 | P37: 0 | Q37: 0 | R37: 0 | S37: 0 | T37: 0 | U37: 0 | V37: 0 | W37: 0 | X37: 0 | Y37: 0 | Z37: 0 | AA37: 0 | AB37: 0 | AC37: 0 | AD37: 0 | AE37: 0 | AF37: 0 | AG37: 0 | AH37: 0 | AI37: 0 | AJ37: 0

Sheet Charizar
A1: 0 | B1: 0 | C1: 0 | D1: 0 | E1: 0 | F1: 0 | G1: 0 | H1: 0 | I1: 0 | J1: 0 | K1: 0 | L1: 0 | M1: 0 | N1: 0 | O1: 0 | P1: 0 | Q1: 0 | R1: 0 | S1: 0 | T1: 0 | U1: 0 | V1: 0 | W1: 0 | X1: 0 | Y1: 0 | Z1: 0 | AA1: 0 | AB1: 0 | AC1: 0 | AD1: 0 | AE1: 0 | AF1: 0 | AG1: 0 | AH1: 0 | AI1: 0 | AJ1: 0
A2: 0 | B2: 0 | C2: 0 | D2: 0 | E2: 0 | F2: 0 | G2: 0 | H2: 0 | I2: 0 | J2: 0 | K2: 0 | L2: 0 | M2: 0 | N2: 0 | O2: 0 | P2: 0 | Q2: 0 | R2: 0 | S2: 0 | T2: 0 | U2: 0 | V2: 0 | W2: 0 | X2: 0 | Y2: 0 | Z2: 0 | AA2: 0 | AB2: 0 | AC2: 0 | AD2: 0 | AE2: 0 | AF2: 0 | AG2: 0 | AH2: 0 | AI2: 0 | AJ2: 0
A3: 0 | B3: 0 | C3: 0 | D3: 0 | E3: 0 | F3: 0 | G3: 0 | H3: 0 | I3: 0 | J3: 0 | K3: 0 | L3: 0 | M3: 0 | N3: 0 | O3: 0 | P3: 0 | Q3: 0 | R3: 0 | S3: 0 | T3: 0 | U3: 0 | V3: 0 | W3: 0 | X3: 0 | Y3: 0 | Z3: 0 | AA3: 0 | AB3: 0 | AC3: 0 | AD3: 0 | AE3: 0 | AF3: 0 | AG3: 0 | AH3: 0 | AI3: 0 | AJ3: 0
A4: 0 | B4: 0 | C4: 0 | D4: 0 | E4: 0 | F4: 0 | G4: 0 | H4: 0 | I4: 0 | J4: 0 | K4: 0 | L4: 0 | M4: 0 | N4: 1 | O4: 1 | P4: 1 | Q4: 0 | R4: 0 | S4: 0 | T4: 1 | U4: 1 | V4: 1 | W4: 0 | X4: 0 | Y4: 0 | Z4: 0 | AA4: 0 | AB4: 0 | AC4: 0 | AD4: 0 | AE4: 0 | AF4: 0 | AG4: 0 | AH4: 0 | AI4: 0 | AJ4: 0
A5: 0 | B5: 0 | C5: 0 | D5: 0 | E5: 0 | F5: 0 | G5: 0 | H5: 0 | I5: 0 | J5: 0 | K5: 0 | L5: 1 | M5: 1 | N5: 12 | O5: 12 | P5: 1 | Q5: 0 | R5: 0 | S5: 0 | T5: 1 | U5: 12 | V5: 12 | W5: 1 | X5: 1 | Y5: 1 | Z5: 0 | AA5: 0 | AB5: 0 | AC5: 0 | AD5: 0 | AE5: 0 | AF5: 0 | AG5: 0 | AH5: 0 | AI5: 0 | AJ5: 0
A6: 0 | B6: 0 | C6: 0 | D6: 0 | E6: 0 | F6: 0 | G6: 0 | H6: 0 | I6: 0 | J6: 1 | K6: 1 | L6: 12 | M6: 12 | N6: 12 | O6: 1 | P6: 0 | Q6: 0 | R6: 0 | S6: 0 | T6: 0 | U6: 1 | V6: 12 | W6: 12 | X6: 12 | Y6: 12 | Z6: 1 | AA6: 1 | AB6: 0 | AC6: 0 | AD6: 0 | AE6: 0 | AF6: 0 | AG6: 0 | AH6: 0 | AI6: 0 | AJ6: 0
A7: 0 | B7: 0 | C7: 0 | D7: 0 | E7: 0 | F7: 0 | G7: 0 | H7: 0 | I7: 1 | J7: 12 | K7: 12 | L7: 12 | M7: 12 | N7: 1 | O7: 0 | P7: 0 | Q7: 0 | R7: 0 | S7: 0 | T7: 0 | U7: 1 | V7: 12 | W7: 1 | X7: 1 | Y7: 1 | Z7: 12 | AA7: 12 | AB7: 1 | AC7: 0 | AD7: 0 | AE7: 0 | AF7: 0 | AG7: 0 | AH7: 0 | AI7: 0 | AJ7: 0
A8: 0 | B8: 0 | C8: 0 | D8: 0 | E8: 0 | F8: 0 | G8: 0 | H8: 1 | I8: 12 | J8: 12 | K8: 12 | L8: 12 | M8: 12 | N8: 1 | O8: 0 | P8: 0 | Q8: 0 | R8: 0 | S8: 0 | T8: 0 | U8: 1 | V8: 12 | W8: 1 | X8: 14 | Y8: 14 | Z8: 1 | AA8: 1 | AB8: 12 | AC8: 1 | AD8: 0 | AE8: 0 | AF8: 0 | AG8: 0 | AH8: 0 | AI8: 0 | AJ8: 0
A9: 0 | B9: 0 | C9: 0 | D9: 0 | E9: 0 | F9: 1 | G9: 1 | H9: 1 | I9: 12 | J9: 1 | K9: 6 | L9: 12 | M9: 12 | N9: 12 | O9: 1 | P9: 0 | Q9: 0 | R9: 0 | S9: 0 | T9: 0 | U9: 1 | V9: 12 | W9: 1 | X9: 14 | Y9: 14 | Z9: 14 | AA9: 14 | AB9: 1 | AC9: 12 | AD9: 1 | AE9: 0 | AF9: 0 | AG9: 0 | AH9: 0 | AI9: 0 | AJ9: 0
A10: 0 | B10: 0 | C10: 0 | D10: 0 | E10: 1 | F10: 12 | G10: 12 | H10: 12 | I10: 12 | J10: 1 | K10: 6 | L10: 12 | M10: 12 | N10: 12 | O10: 12 | P10: 1 | Q10: 0 | R10: 0 | S10: 0 | T10: 0 | U10: 1 | V10: 12 | W10: 1 | X10: 14 | Y10: 14 | Z10: 14 | AA10: 14 | AB10: 14 | AC10: 1 | AD10: 12 | AE10: 1 | AF10: 0 | AG10: 0 | AH10: 0 | AI10: 0 | AJ10: 0
A11: 0 | B11: 0 | C11: 0 | D11: 0 | E11: 1 | F11: 12 | G11: 1 | H11: 12 | I11: 12 | J11: 12 | K11: 12 | L11: 12 | M11: 12 | N11: 12 | O11: 12 | P11: 1 | Q11: 0 | R11: 0 | S11: 0 | T11: 0 | U11: 1 | V11: 12 | W11: 1 | X11: 14 | Y11: 14 | Z11: 14 | AA11: 14 | AB11: 14 | AC11: 1 | AD11: 12 | AE11: 1 | AF11: 0 | AG11: 0 | AH11: 0 | AI11: 0 | AJ11: 0
A12: 0 | B12: 0 | C12: 0 | D12: 0 | E12: 0 | F12: 1 | G12: 1 | H12: 1 | I12: 1 | J12: 1 | K12: 12 | L12: 12 | M12: 1 | N12: 12 | O12: 12 | P12: 12 | Q12: 1 | R12: 0 | S12: 0 | T12: 1 | U12: 12 | V12: 12 | W12: 1 | X12: 14 | Y12: 14 | Z12: 14 | AA12: 14 | AB12: 14 | AC12: 14 | AD12: 1 | AE12: 12 | AF12: 1 | AG12: 0 | AH12: 0 | AI12: 0 | AJ12: 0
... A14: 0 | B14: 0 | C14: 0 | D14: 7 | E14: 7 | F14: 0 | G14: 7 | H14: 1 | I14: 12 | J14: 12 | K14: 1 | L14: 0 | M14: 0 | N14: 1 | O14: 12 | P14: 12 | Q14: 12 | R14: 1 | S14: 1 | T14: 12 | U14: 12 | V14: 1 | W14: 14 | X14: 14 | Y14: 14 | Z14: 14 | AA14: 14 | AB14: 14 | AC14: 14 | AD14: 14 | AE14: 1 | AF14: 12 | AG14: 1 | AH14: 0 | AI14: 0 | AJ14: 0
A15: 0 | B15: 0 | C15: 7 | D15: 7 | E15: 13 | F15: 7 | G15: 0 | H15: 0 | I15: 1 | J15: 1 | K15: 0 | L15: 0 | M15: 0 | N15: 1 | O15: 12 | P15: 12 | Q15: 12 | R15: 1 | S15: 12 | T15: 12 | U15: 1 | V15: 14 | W15: 14 | X15: 14 | Y15: 14 | Z15: 1 | AA15: 1 | AB15: 1 | AC15: 14 | AD15: 14 | AE15: 1 | AF15: 12 | AG15: 1 | AH15: 0 | AI15: 0 | AJ15: 0 | AP15: 1
A16: 0 | B16: 0 | C16: 0 | D16: 7 | E16: 13 | F16: 13 | G16: 0 | H16: 0 | I16: 0 | J16: 0 | K16: 0 | L16: 0 | M16: 0 | N16: 1 | O16: 12 | P16: 12 | Q16: 12 | R16: 12 | S16: 12 | T16: 1 | U16: 1 | V16: 14 | W16: 14 | X16: 14 | Y16: 1 | Z16: 0 | AA16: 0 | AB16: 0 | AC16: 1 | AD16: 14 | AE16: 1 | AF16: 12 | AG16: 1 | AH16: 0 | AI16: 0 | AJ16: 0
A17: 0 | B17: 0 | C17: 0 | D17: 0 | E17: 7 | F17: 0 | G17: 0 | H17: 0 | I17: 0 | J17: 1 | K17: 1 | L17: 1 | M17: 1 | N17: 12 | O17: 12 | P17: 12 | Q17: 12 | R17: 12 | S17: 12 | T17: 12 | U17: 1 | V17: 14 | W17: 1 | X17: 1 | Y17: 0 | Z17: 0 | AA17: 0 | AB17: 1 | AC17: 0 | AD17: 1 | AE17: 1 | AF17: 12 | AG17: 1 | AH17: 0 | AI17: 0 | AJ17: 0
A18: 0 | B18: 0 | C18: 0 | D18: 0 | E18: 0 | F18: 0 | G18: 0 | H18: 0 | I18: 1 | J18: 12 | K18: 12 | L18: 1 | M18: 1 | N18: 12 | O18: 12 | P18: 12 | Q18: 12 | R18: 1 | S18: 12 | T18: 12 | U18: 12 | V18: 1 | W18: 0 | X18: 0 | Y18: 0 | Z18: 0 | AA18: 1 | AB18: 7 | AC18: 1 | AD18: 0 | AE18: 1 | AF18: 12 | AG18: 1 | AH18: 0 | AI18: 0 | AJ18: 0
A19: 0 | B19: 0 | C19: 0 | D19: 0 | E19: 0 | F19: 0 | G19: 0 | H19: 0 | I19: 1 | J19: 1 | K19: 12 | L19: 1 | M19: 8 | N19: 8 | O19: 12 | P19: 1 | Q19: 1 | R19: 12 | S19: 12 | T19: 1 | U19: 12 | V19: 1 | W19: 0 | X19: 0 | Y19: 0 | Z19: 0 | AA19: 1 | AB19: 7 | AC19: 7 | AD19: 1 | AE19: 0 | AF19: 1 | AG19: 0 | AH19: 0 | AI19: 0 | AJ19: 0
A20: 0 | B20: 0 | C20: 0 | D20: 0 | E20: 0 | F20: 0 | G20: 0 | H20: 0 | I20: 0 | J20: 1 | K20: 1 | L20: 1 | M20: 8 | N20: 8 | O20: 1 | P20: 12 | Q20: 12 | R20: 12 | S20: 12 | T20: 1 | U20: 12 | V20: 12 | W20: 1 | X20: 0 | Y20: 0 | Z20: 0 | AA20: 1 | AB20: 7 | AC20: 13 | AD20: 7 | AE20: 1 | AF20: 0 | AG20: 0 | AH20: 0 | AI20: 0 | AJ20: 0
A21: 0 | B21: 0 | C21: 0 | D21: 0 | E21: 0 | F21: 0 | G21: 0 | H21: 0 | I21: 0 | J21: 0 | K21: 0 | L21: 1 | M21: 8 | N21: 8 | O21: 1 | P21: 6 | Q21: 12 | R21: 12 | S21: 1 | T21: 12 | U21: 12 | V21: 12 | W21: 1 | X21: 0 | Y21: 0 | Z21: 0 | AA21: 0 | AB21: 1 | AC21: 13 | AD21: 7 | AE21: 1 | AF21: 0 | AG21: 0 | AH21: 0 | AI21: 0 | AJ21: 0
A22: 0 | B22: 0 | C22: 0 | D22: 0 | E22: 0 | F22: 0 | G22: 0 | H22: 0 | I22: 0 | J22: 0 | K22: 1 | L22: 12 | M22: 8 | N22: 8 | O22: 8 | P22: 1 | Q22: 1 | R22: 1 | S22: 12 | T22: 12 | U22: 12 | V22: 12 | W22: 12 | X22: 1 | Y22: 0 | Z22: 0 | AA22: 0 | AB22: 0 | AC22: 1 | AD22: 12 | AE22: 1 | AF22: 0 | AG22: 0 | AH22: 0 | AI22: 0 | AJ22: 0
A23: 0 | B23: 0 | C23: 0 | D23: 0 | E23: 0 | F23: 0 | G23: 0 | H23: 0 | I23: 0 | J23: 0 | K23: 1 | L23: 12 | M23: 8 | N23: 8 | O23: 8 | P23: 8 | Q23: 8 | R23: 1 | S23: 12 | T23: 12 | U23: 12 | V23: 12 | W23: 12 | X23: 1 | Y23: 1 | Z23: 1 | AA23: 1 | AB23: 1 | AC23: 12 | AD23: 12 | AE23: 1 | AF23: 0 | AG23: 0 | AH23: 0 | AI23: 0 | AJ23: 0
A24: 0 | B24: 0 | C24: 0 | D24: 0 | E24: 0 | F24: 0 | G24: 0 | H24: 0 | I24: 0 | J24: 0 | K24: 1 | L24: 12 | M24: 1 | N24: 8 | O24: 8 | P24: 8 | Q24: 1 | R24: 12 | S24: 12 | T24: 12 | U24: 12 | V24: 12 | W24: 12 | X24: 1 | Y24: 12 | Z24: 12 | AA24: 12 | AB24: 12 | AC24: 12 | AD24: 1 | AE24: 0 | AF24: 0 | AG24: 0 | AH24: 0 | AI24: 0 | AJ24: 0
A25: 0 | B25: 0 | C25: 0 | D25: 0 | E25: 0 | F25: 0 | G25: 0 | H25: 0 | I25: 0 | J25: 0 | K25: 0 | L25: 1 | M25: 12 | N25: 1 | O25: 8 | P25: 8 | Q25: 1 | R25: 12 | S25: 12 | T25: 12 | U25: 12 | V25: 12 | W25: 12 | X25: 1 | Y25: 12 | Z25: 12 | AA25: 12 | AB25: 12 | AC25: 12 | AD25: 1 | AE25: 0 | AF25: 0 | AG25: 0 | AH25: 0 | AI25: 0 | AJ25: 0
A26: 0 | B26: 0 | C26: 0 | D26: 0 | E26: 0 | F26: 0 | G26: 0 | H26: 0 | I26: 0 | J26: 0 | K26: 0 | L26: 1 | M26: 12 | N26: 12 | O26: 1 | P26: 1 | Q26: 12 | R26: 1 | S26: 12 | T26: 12 | U26: 12 | V26: 12 | W26: 1 | X26: 12 | Y26: 12 | Z26: 12 | AA26: 12 | AB26: 1 | AC26: 1 | AD26: 0 | AE26: 0 | AF26: 0 | AG26: 0 | AH26: 0 | AI26: 0 | AJ26: 0
A27: 0 | B27: 0 | C27: 0 | D27: 0 | E27: 0 | F27: 0 | G27: 0 | H27: 0 | I27: 0 | J27: 0 | K27: 1 | L27: 6 | M27: 12 | N27: 12 | O27: 12 | P27: 1 | Q27: 1 | R27: 1 | S27: 1 | T27: 12 | U27: 12 | V27: 12 | W27: 1 | X27: 1 | Y27: 1 | Z27: 1 | AA27: 1 | AB27: 0 | AC27: 0 | AD27: 0 | AE27: 0 | AF27: 0 | AG27: 0 | AH27: 0 | AI27: 0 | AJ27: 0
... A36: 0 | B36: 0 | C36: 0 | D36: 0 | E36: 0 | F36: 0 | G36: 0 | H36: 0 | I36: 0 | J36: 0 | K36: 0 | L36: 0 | M36: 0 | N36: 0 | O36: 0 | P36: 0 | Q36: 0 | R36: 0 | S36: 0 | T36: 0 | U36: 0 | V36: 0 | W36: 0 | X36: 0 | Y36: 0 | Z36: 0 | AA36: 0 | AB36: 0 | AC36: 0 | AD36: 0 | AE36: 0 | AF36: 0 | AG36: 0 | AH36: 0 | AI36: 0 | AJ36: 0

Sheet transpuestaB
A1: {=TRANSPOSE(Charizar!A1:AK36)} -> 0 | B1: 0 | C1: 0 | D1: 0 | E1: 0 | F1: 0 | G1: 0 | H1: 0 | I1: 0 | J1: 0 | K1: 0 | L1: 0 | M1: 0 | N1: 0 | O1: 0 | P1: 0 | Q1: 0 | R1: 0 | S1: 0 | T1: 0 | U1: 0 | V1: 0 | W1: 0 | X1: 0 | Y1: 0 | Z1: 0 | AA1: 0 | AB1: 0 | AC1: 0 | AD1: 0 | AE1: 0 | AF1: 0 | AG1: 0 | AH1: 0 | AI1: 0 | AJ1: 0
A2: 0 | B2: 0 | C2: 0 | D2: 0 | E2: 0 | F2: 0 | G2: 0 | H2: 0 | I2: 0 | J2: 0 | K2: 0 | L2: 0 | M2: 0 | N2: 0 | O2: 0 | P2: 0 | Q2: 0 | R2: 0 | S2: 0 | T2: 0 | U2: 0 | V2: 0 | W2: 0 | X2: 0 | Y2: 0 | Z2: 0 | AA2: 0 | AB2: 0 | AC2: 0 | AD2: 0 | AE2: 0 | AF2: 0 | AG2: 0 | AH2: 0 | AI2: 0 | AJ2: 0
A3: 0 | B3: 0 | C3: 0 | D3: 0 | E3: 0 | F3: 0 | G3: 0 | H3: 0 | I3: 0 | J3: 0 | K3: 0 | L3: 0 | M3: 0 | N3: 0 | O3: 7 | P3: 0 | Q3: 0 | R3: 0 | S3: 0 | T3: 0 | U3: 0 | V3: 0 | W3: 0 | X3: 0 | Y3: 0 | Z3: 0 | AA3: 0 | AB3: 0 | AC3: 0 | AD3: 0 | AE3: 0 | AF3: 0 | AG3: 0 | AH3: 0 | AI3: 0 | AJ3: 0
A4: 0 | B4: 0 | C4: 0 | D4: 0 | E4: 0 | F4: 0 | G4: 0 | H4: 0 | I4: 0 | J4: 0 | K4: 0 | L4: 0 | M4: 7 | N4: 7 | O4: 7 | P4: 7 | Q4: 0 | R4: 0 | S4: 0 | T4: 0 | U4: 0 | V4: 0 | W4: 0 | X4: 0 | Y4: 0 | Z4: 0 | AA4: 0 | AB4: 0 | AC4: 0 | AD4: 0 | AE4: 0 | AF4: 0 | AG4: 0 | AH4: 0 | AI4: 0 | AJ4: 0
A5: 0 | B5: 0 | C5: 0 | D5: 0 | E5: 0 | F5: 0 | G5: 0 | H5: 0 | I5: 0 | J5: 1 | K5: 1 | L5: 0 | M5: 0 | N5: 7 | O5: 13 | P5: 13 | Q5: 7 | R5: 0 | S5: 0 | T5: 0 | U5: 0 | V5: 0 | W5: 0 | X5: 0 | Y5: 0 | Z5: 0 | AA5: 0 | AB5: 0 | AC5: 0 | AD5: 0 | AE5: 0 | AF5: 0 | AG5: 0 | AH5: 0 | AI5: 0 | AJ5: 0
A6: 0 | B6: 0 | C6: 0 | D6: 0 | E6: 0 | F6: 0 | G6: 0 | H6: 0 | I6: 1 | J6: 12 | K6: 12 | L6: 1 | M6: 0 | N6: 0 | O6: 7 | P6: 13 | Q6: 0 | R6: 0 | S6: 0 | T6: 0 | U6: 0 | V6: 0 | W6: 0 | X6: 0 | Y6: 0 | Z6: 0 | AA6: 0 | AB6: 0 | AC6: 0 | AD6: 0 | AE6: 0 | AF6: 0 | AG6: 0 | AH6: 0 | AI6: 0 | AJ6: 0
A7: 0 | B7: 0 | C7: 0 | D7: 0 | E7: 0 | F7: 0 | G7: 0 | H7: 0 | I7: 1 | J7: 12 | K7: 1 | L7: 1 | M7: 0 | N7: 7 | O7: 0 | P7: 0 | Q7: 0 | R7: 0 | S7: 0 | T7: 0 | U7: 0 | V7: 0 | W7: 0 | X7: 0 | Y7: 0 | Z7: 0 | AA7: 0 | AB7: 0 | AC7: 0 | AD7: 0 | AE7: 0 | AF7: 0 | AG7: 0 | AH7: 0 | AI7: 0 | AJ7: 0
A8: 0 | B8: 0 | C8: 0 | D8: 0 | E8: 0 | F8: 0 | G8: 0 | H8: 1 | I8: 1 | J8: 12 | K8: 12 | L8: 1 | M8: 0 | N8: 1 | O8: 0 | P8: 0 | Q8: 0 | R8: 0 | S8: 0 | T8: 0 | U8: 0 | V8: 0 | W8: 0 | X8: 0 | Y8: 0 | Z8: 0 | AA8: 0 | AB8: 0 | AC8: 0 | AD8: 0 | AE8: 0 | AF8: 0 | AG8: 0 | AH8: 0 | AI8: 0 | AJ8: 0
A9: 0 | B9: 0 | C9: 0 | D9: 0 | E9: 0 | F9: 0 | G9: 1 | H9: 12 | I9: 12 | J9: 12 | K9: 12 | L9: 1 | M9: 1 | N9: 12 | O9: 1 | P9: 0 | Q9: 0 | R9: 1 | S9: 1 | T9: 0 | U9: 0 | V9: 0 | W9: 0 | X9: 0 | Y9: 0 | Z9: 0 | AA9: 0 | AB9: 0 | AC9: 0 | AD9: 0 | AE9: 0 | AF9: 0 | AG9: 0 | AH9: 0 | AI9: 0 | AJ9: 0
A10: 0 | B10: 0 | C10: 0 | D10: 0 | E10: 0 | F10: 1 | G10: 12 | H10: 12 | I10: 1 | J10: 1 | K10: 12 | L10: 1 | M10: 12 | N10: 12 | O10: 1 | P10: 0 | Q10: 1 | R10: 12 | S10: 1 | T10: 1 | U10: 0 | V10: 0 | W10: 0 | X10: 0 | Y10: 0 | Z10: 0 | AA10: 0 | AB10: 0 | AC10: 0 | AD10: 0 | AE10: 0 | AF10: 0 | AG10: 0 | AH10: 0 | AI10: 0 | AJ10: 0
A11: 0 | B11: 0 | C11: 0 | D11: 0 | E11: 0 | F11: 1 | G11: 12 | H11: 12 | I11: 6 | J11: 6 | K11: 12 | L11: 12 | M11: 12 | N11: 1 | O11: 0 | P11: 0 | Q11: 1 | R11: 12 | S11: 12 | T11: 1 | U11: 0 | V11: 1 | W11: 1 | X11: 1 | Y11: 0 | Z11: 0 | AA11: 1 | AB11: 1 | AC11: 0 | AD11: 0 | AE11: 0 | AF11: 0 | AG11: 0 | AH11: 0 | AI11: 0 | AJ11: 0
A12: 0 | B12: 0 | C12: 0 | D12: 0 | E12: 1 | F12: 12 | G12: 12 | H12: 12 | I12: 12 | J12: 12 | K12: 12 | L12: 12 | M12: 1 | N12: 0 | O12: 0 | P12: 0 | Q12: 1 | R12: 1 | S12: 1 | T12: 1 | U12: 1 | V12: 12 | W12: 12 | X12: 12 | Y12: 1 | Z12: 1 | AA12: 6 | AB12: 1 | AC12: 0 | AD12: 0 | AE12: 0 | AF12: 0 | AG12: 0 | AH12: 0 | AI12: 0 | AJ12: 0
A13: 0 | B13: 0 | C13: 0 | D13: 0 | E13: 1 | F13: 12 | G13: 12 | H13: 12 | I13: 12 | J13: 12 | K13: 12 | L13: 1 | M13: 1 | N13: 0 | O13: 0 | P13: 0 | Q13: 1 | R13: 1 | S13: 8 | T13: 8 | U13: 8 | V13: 8 | W13: 8 | X13: 1 | Y13: 12 | Z13: 12 | AA13: 12 | AB13: 1 | AC13: 0 | AD13: 0 | AE13: 0 | AF13: 0 | AG13: 0 | AH13: 0 | AI13: 0 | AJ13: 0
A14: 0 | B14: 0 | C14: 0 | D14: 1 | E14: 12 | F14: 12 | G14: 1 | H14: 1 | I14: 12 | J14: 12 | K14: 12 | L14: 12 | M14: 12 | N14: 1 | O14: 1 | P14: 1 | Q14: 12 | R14: 12 | S14: 8 | T14: 8 | U14: 8 | V14: 8 | W14: 8 | X14: 8 | Y14: 1 | Z14: 12 | AA14: 12 | AB14: 1 | AC14: 0 | AD14: 0 | AE14: 0 | AF14: 0 | AG14: 0 | AH14: 0 | AI14: 0 | AJ14: 0
A15: 0 | B15: 0 | C15: 0 | D15: 1 | E15: 12 | F15: 1 | G15: 0 | H15: 0 | I15: 1 | J15: 12 | K15: 12 | L15: 12 | M15: 12 | N15: 12 | O15: 12 | P15: 12 | Q15: 12 | R15: 12 | S15: 12 | T15: 1 | U15: 1 | V15: 8 | W15: 8 | X15: 8 | Y15: 8 | Z15: 1 | AA15: 12 | AB15: 1 | AC15: 0 | AD15: 0 | AE15: 0 | AF15: 0 | AG15: 0 | AH15: 0 | AI15: 0 | AJ15: 0 | AP15: 1
A16: 0 | B16: 0 | C16: 0 | D16: 1 | E16: 1 | F16: 0 | G16: 0 | H16: 0 | I16: 0 | J16: 1 | K16: 1 | L16: 12 | M16: 12 | N16: 12 | O16: 12 | P16: 12 | Q16: 12 | R16: 12 | S16: 1 | T16: 12 | U16: 6 | V16: 1 | W16: 8 | X16: 8 | Y16: 8 | Z16: 1 | AA16: 1 | AB16: 0 | AC16: 0 | AD16: 0 | AE16: 0 | AF16: 0 | AG16: 0 | AH16: 0 | AI16: 0 | AJ16: 0
A17: 0 | B17: 0 | C17: 0 | D17: 0 | E17: 0 | F17: 0 | G17: 0 | H17: 0 | I17: 0 | J17: 0 | K17: 0 | L17: 1 | M17: 1 | N17: 12 | O17: 12 | P17: 12 | Q17: 12 | R17: 12 | S17: 1 | T17: 12 | U17: 12 | V17: 1 | W17: 8 | X17: 1 | Y17: 1 | Z17: 12 | AA17: 1 | AB17: 0 | AC17: 0 | AD17: 0 | AE17: 0 | AF17: 0 | AG17: 0 | AH17: 0 | AI17: 0 | AJ17: 0
A18: 0 | B18: 0 | C18: 0 | D18: 0 | E18: 0 | F18: 0 | G18: 0 | H18: 0 | I18: 0 | J18: 0 | K18: 0 | L18: 0 | M18: 0 | N18: 1 | O18: 1 | P18: 12 | Q18: 12 | R18: 1 | S18: 12 | T18: 12 | U18: 12 | V18: 1 | W18: 1 | X18: 12 | Y18: 12 | Z18: 1 | AA18: 1 | AB18: 1 | AC18: 0 | AD18: 0 | AE18: 0 | AF18: 0 | AG18: 0 | AH18: 0 | AI18: 0 | AJ18: 0
A19: 0 | B19: 0 | C19: 0 | D19: 0 | E19: 0 | F19: 0 | G19: 0 | H19: 0 | I19: 0 | J19: 0 | K19: 0 | L19: 0 | M19: 0 | N19: 1 | O19: 12 | P19: 12 | Q19: 12 | R19: 12 | S19: 12 | T19: 12 | U19: 1 | V19: 12 | W19: 12 | X19: 12 | Y19: 12 | Z19: 12 | AA19: 1 | AB19: 6 | AC19: 1 | AD19: 0 | AE19: 0 | AF19: 0 | AG19: 0 | AH19: 0 | AI19: 0 | AJ19: 0
A20: 0 | B20: 0 | C20: 0 | D20: 1 | E20: 1 | F20: 0 | G20: 0 | H20: 0 | I20: 0 | J20: 0 | K20: 0 | L20: 1 | M20: 1 | N20: 12 | O20: 12 | P20: 1 | Q20: 12 | R20: 12 | S20: 1 | T20: 1 | U20: 12 | V20: 12 | W20: 12 | X20: 12 | Y20: 12 | Z20: 12 | AA20: 12 | AB20: 12 | AC20: 1 | AD20: 0 | AE20: 0 | AF20: 0 | AG20: 0 | AH20: 0 | AI20: 0 | AJ20: 0
A21: 0 | B21: 0 | C21: 0 | D21: 1 | E21: 12 | F21: 1 | G21: 1 | H21: 1 | I21: 1 | J21: 1 | K21: 1 | L21: 12 | M21: 12 | N21: 12 | O21: 1 | P21: 1 | Q21: 1 | R21: 12 | S21: 12 | T21: 12 | U21: 12 | V21: 12 | W21: 12 | X21: 12 | Y21: 12 | Z21: 12 | AA21: 12 | AB21: 1 | AC21: 1 | AD21: 0 | AE21: 0 | AF21: 0 | AG21: 0 | AH21: 0 | AI21: 0 | AJ21: 0
A22: 0 | B22: 0 | C22: 0 | D22: 1 | E22: 12 | F22: 12 | G22: 12 | H22: 12 | I22: 12 | J22: 12 | K22: 12 | L22: 12 | M22: 1 | N22: 1 | O22: 14 | P22: 14 | Q22: 14 | R22: 1 | S22: 1 | T22: 12 | U22: 12 | V22: 12 | W22: 12 | X22: 12 | Y22: 12 | Z22: 12 | AA22: 12 | AB22: 6 | AC22: 1 | AD22: 0 | AE22: 0 | AF22: 0 | AG22: 0 | AH22: 0 | AI22: 0 | AJ22: 0
A23: 0 | B23: 0 | C23: 0 | D23: 0 | E23: 1 | F23: 12 | G23: 1 | H23: 1 | I23: 1 | J23: 1 | K23: 1 | L23: 1 | M23: 14 | N23: 14 | O23: 14 | P23: 14 | Q23: 1 | R23: 0 | S23: 0 | T23: 1 | U23: 1 | V23: 12 | W23: 12 | X23: 12 | Y23: 12 | Z23: 1 | AA23: 1 | AB23: 1 | AC23: 1 | AD23: 0 | AE23: 0 | AF23: 0 | AG23: 0 | AH23: 0 | AI23: 0 | AJ23: 0
A24: 0 | B24: 0 | C24: 0 | D24: 0 | E24: 1 | F24: 12 | G24: 1 | H24: 14 | I24: 14 | J24: 14 | K24: 14 | L24: 14 | M24: 14 | N24: 14 | O24: 14 | P24: 14 | Q24: 1 | R24: 0 | S24: 0 | T24: 0 | U24: 0 | V24: 1 | W24: 1 | X24: 1 | Y24: 1 | Z24: 12 | AA24: 1 | AB24: 0 | AC24: 0 | AD24: 0 | AE24: 0 | AF24: 0 | AG24: 0 | AH24: 0 | AI24: 0 | AJ24: 0
A25: 0 | B25: 0 | C25: 0 | D25: 0 | E25: 1 | F25: 12 | G25: 1 | H25: 14 | I25: 14 | J25: 14 | K25: 14 | L25: 14 | M25: 14 | N25: 14 | O25: 14 | P25: 1 | Q25: 0 | R25: 0 | S25: 0 | T25: 0 | U25: 0 | V25: 0 | W25: 1 | X25: 12 | Y25: 12 | Z25: 12 | AA25: 1 | AB25: 0 | AC25: 0 | AD25: 0 | AE25: 0 | AF25: 0 | AG25: 0 | AH25: 0 | AI25: 0 | AJ25: 0
A26: 0 | B26: 0 | C26: 0 | D26: 0 | E26: 0 | F26: 1 | G26: 12 | H26: 1 | I26: 14 | J26: 14 | K26: 14 | L26: 14 | M26: 14 | N26: 14 | O26: 1 | P26: 0 | Q26: 0 | R26: 0 | S26: 0 | T26: 0 | U26: 0 | V26: 0 | W26: 1 | X26: 12 | Y26: 12 | Z26: 12 | AA26: 1 | AB26: 0 | AC26: 0 | AD26: 0 | AE26: 0 | AF26: 0 | AG26: 0 | AH26: 0 | AI26: 0 | AJ26: 0
A27: 0 | B27: 0 | C27: 0 | D27: 0 | E27: 0 | F27: 1 | G27: 12 | H27: 1 | I27: 14 | J27: 14 | K27: 14 | L27: 14 | M27: 14 | N27: 14 | O27: 1 | P27: 0 | Q27: 0 | R27: 1 | S27: 1 | T27: 1 | U27: 0 | V27: 0 | W27: 1 | X27: 12 | Y27: 12 | Z27: 12 | AA27: 1 | AB27: 0 | AC27: 0 | AD27: 0 | AE27: 0 | AF27: 0 | AG27: 0 | AH27: 0 | AI27: 0 | AJ27: 0
... A37: 0 | B37: 0 | C37: 0 | D37: 0 | E37: 0 | F37: 0 | G37: 0 | H37: 0 | I37: 0 | J37: 0 | K37: 0 | L37: 0 | M37: 0 | N37: 0 | O37: 0 | P37: 0 | Q37: 0 | R37: 0 | S37: 0 | T37: 0 | U37: 0 | V37: 0 | W37: 0 | X37: 0 | Y37: 0 | Z37: 0 | AA37: 0 | AB37: 0 | AC37: 0 | AD37: 0 | AE37: 0 | AF37: 0 | AG37: 0 | AH37: 0 | AI37: 0 | AJ37: 0

Sheet HollowKnight
A1: 0 | B1: 0 | C1: 0 | D1: 0 | E1: 0 | F1: 0 | G1: 0 | H1: 0 | I1: 0 | J1: 0 | K1: 0 | L1: 0 | M1: 0 | N1: 0 | O1: 0 | P1: 0 | Q1: 0 | R1: 0 | S1: 0 | T1: 0 | U1: 0 | V1: 0 | W1: 0 | X1: 0 | Y1: 0 | Z1: 0 | AA1: 0 | AB1: 0 | AC1: 0 | AD1: 0 | AE1: 0 | AF1: 0 | AG1: 0 | AH1: 0 | AI1: 0 | AJ1: 0 | AK1: 0
A2: 0 | B2: 0 | C2: 0 | D2: 0 | E2: 0 | F2: 0 | G2: 0 | H2: 0 | I2: 0 | J2: 0 | K2: 0 | L2: 0 | M2: 0 | N2: 0 | O2: 0 | P2: 0 | Q2: 0 | R2: 0 | S2: 0 | T2: 0 | U2: 0 | V2: 0 | W2: 0 | X2: 0 | Y2: 0 | Z2: 0 | AA2: 0 | AB2: 0 | AC2: 0 | AD2: 0 | AE2: 0 | AF2: 0 | AG2: 0 | AH2: 0 | AI2: 0 | AJ2: 0 | AK2: 0
A3: 0 | B3: 0 | C3: 0 | D3: 0 | E3: 0 | F3: 0 | G3: 0 | H3: 0 | I3: 0 | J3: 0 | K3: 0 | L3: 0 | M3: 0 | N3: 0 | O3: 0 | P3: 0 | Q3: 0 | R3: 0 | S3: 0 | T3: 0 | U3: 0 | V3: 0 | W3: 0 | X3: 0 | Y3: 0 | Z3: 0 | AA3: 0 | AB3: 0 | AC3: 0 | AD3: 0 | AE3: 0 | AF3: 0 | AG3: 0 | AH3: 0 | AI3: 0 | AJ3: 0 | AK3: 0
A4: 0 | B4: 0 | C4: 0 | D4: 0 | E4: 0 | F4: 0 | G4: 0 | H4: 0 | I4: 0 | J4: 0 | K4: 0 | L4: 1 | M4: 1 | N4: 0 | O4: 0 | P4: 0 | Q4: 0 | R4: 0 | S4: 0 | T4: 0 | U4: 1 | V4: 1 | W4: 0 | X4: 0 | Y4: 0 | Z4: 0 | AA4: 0 | AB4: 0 | AC4: 0 | AD4: 0 | AE4: 0 | AF4: 0 | AG4: 0 | AH4: 0 | AI4: 0 | AJ4: 0 | AK4: 0
A5: 0 | B5: 0 | C5: 0 | D5: 0 | E5: 0 | F5: 0 | G5: 0 | H5: 0 | I5: 0 | J5: 0 | K5: 1 | L5: 9 | M5: 1 | N5: 0 | O5: 0 | P5: 0 | Q5: 0 | R5: 0 | S5: 0 | T5: 0 | U5: 1 | V5: 9 | W5: 1 | X5: 0 | Y5: 0 | Z5: 0 | AA5: 0 | AB5: 0 | AC5: 0 | AD5: 0 | AE5: 0 | AF5: 0 | AG5: 0 | AH5: 0 | AI5: 0 | AJ5: 0 | AK5: 0
A6: 0 | B6: 0 | C6: 0 | D6: 0 | E6: 0 | F6: 0 | G6: 0 | H6: 0 | I6: 0 | J6: 1 | K6: 9 | L6: 0 | M6: 1 | N6: 0 | O6: 0 | P6: 0 | Q6: 0 | R6: 0 | S6: 0 | T6: 0 | U6: 1 | V6: 0 | W6: 9 | X6: 1 | Y6: 0 | Z6: 0 | AA6: 0 | AB6: 0 | AC6: 0 | AD6: 0 | AE6: 0 | AF6: 0 | AG6: 0 | AH6: 0 | AI6: 0 | AJ6: 0 | AK6: 0
A7: 0 | B7: 0 | C7: 0 | D7: 0 | E7: 0 | F7: 0 | G7: 0 | H7: 0 | I7: 1 | J7: 9 | K7: 0 | L7: 1 | M7: 0 | N7: 0 | O7: 0 | P7: 0 | Q7: 0 | R7: 0 | S7: 0 | T7: 0 | U7: 0 | V7: 1 | W7: 0 | X7: 9 | Y7: 1 | Z7: 0 | AA7: 0 | AB7: 0 | AC7: 0 | AD7: 0 | AE7: 0 | AF7: 0 | AG7: 0 | AH7: 0 | AI7: 0 | AJ7: 0 | AK7: 0
A8: 0 | B8: 0 | C8: 0 | D8: 0 | E8: 0 | F8: 0 | G8: 0 | H8: 1 | I8: 9 | J8: 0 | K8: 1 | L8: 0 | M8: 0 | N8: 0 | O8: 0 | P8: 0 | Q8: 0 | R8: 0 | S8: 0 | T8: 0 | U8: 0 | V8: 0 | W8: 1 | X8: 0 | Y8: 9 | Z8: 1 | AA8: 0 | AB8: 0 | AC8: 0 | AD8: 0 | AE8: 0 | AF8: 0 | AG8: 0 | AH8: 0 | AI8: 0 | AJ8: 0 | AK8: 0
A9: 0 | B9: 0 | C9: 0 | D9: 0 | E9: 0 | F9: 0 | G9: 0 | H9: 1 | I9: 9 | J9: 0 | K9: 1 | L9: 0 | M9: 0 | N9: 0 | O9: 0 | P9: 0 | Q9: 0 | R9: 0 | S9: 0 | T9: 0 | U9: 0 | V9: 0 | W9: 1 | X9: 0 | Y9: 9 | Z9: 1 | AA9: 0 | AB9: 0 | AC9: 0 | AD9: 0 | AE9: 0 | AF9: 0 | AG9: 0 | AH9: 0 | AI9: 0 | AJ9: 0 | AK9: 0
A10: 0 | B10: 0 | C10: 0 | D10: 0 | E10: 0 | F10: 0 | G10: 0 | H10: 1 | I10: 9 | J10: 0 | K10: 0 | L10: 1 | M10: 1 | N10: 1 | O10: 1 | P10: 1 | Q10: 1 | R10: 1 | S10: 1 | T10: 1 | U10: 1 | V10: 1 | W10: 0 | X10: 0 | Y10: 9 | Z10: 1 | AA10: 0 | AB10: 0 | AC10: 0 | AD10: 0 | AE10: 0 | AF10: 0 | AG10: 0 | AH10: 0 | AI10: 0 | AJ10: 0 | AK10: 0
A11: 0 | B11: 0 | C11: 0 | D11: 0 | E11: 0 | F11: 0 | G11: 0 | H11: 0 | I11: 1 | J11: 9 | K11: 0 | L11: 0 | M11: 0 | N11: 0 | O11: 0 | P11: 0 | Q11: 0 | R11: 0 | S11: 0 | T11: 0 | U11: 0 | V11: 0 | W11: 0 | X11: 9 | Y11: 1 | Z11: 0 | AA11: 0 | AB11: 0 | AC11: 0 | AD11: 0 | AE11: 0 | AF11: 0 | AG11: 0 | AH11: 0 | AI11: 0 | AJ11: 0 | AK11: 0
A12: 0 | B12: 0 | C12: 0 | D12: 0 | E12: 0 | F12: 0 | G12: 0 | H12: 0 | I12: 0 | J12: 1 | K12: 9 | L12: 0 | M12: 0 | N12: 0 | O12: 0 | P12: 0 | Q12: 0 | R12: 0 | S12: 0 | T12: 0 | U12: 0 | V12: 0 | W12: 9 | X12: 1 | Y12: 0 | Z12: 0 | AA12: 0 | AB12: 0 | AC12: 0 | AD12: 0 | AE12: 0 | AF12: 0 | AG12: 0 | AH12: 0 | AI12: 0 | AJ12: 0 | AK12: 0
... A14: 0 | B14: 0 | C14: 0 | D14: 0 | E14: 0 | F14: 0 | G14: 0 | H14: 0 | I14: 0 | J14: 1 | K14: 9 | L14: 0 | M14: 0 | N14: 0 | O14: 0 | P14: 0 | Q14: 0 | R14: 0 | S14: 0 | T14: 0 | U14: 0 | V14: 0 | W14: 9 | X14: 1 | Y14: 0 | Z14: 0 | AA14: 0 | AB14: 0 | AC14: 0 | AD14: 0 | AE14: 0 | AF14: 0 | AG14: 0 | AH14: 0 | AI14: 0 | AJ14: 0 | AK14: 0
A15: 0 | B15: 0 | C15: 0 | D15: 0 | E15: 0 | F15: 0 | G15: 0 | H15: 0 | I15: 0 | J15: 1 | K15: 9 | L15: 0 | M15: 1 | N15: 1 | O15: 0 | P15: 0 | Q15: 0 | R15: 0 | S15: 0 | T15: 1 | U15: 1 | V15: 0 | W15: 9 | X15: 1 | Y15: 0 | Z15: 0 | AA15: 0 | AB15: 0 | AC15: 0 | AD15: 0 | AE15: 0 | AF15: 0 | AG15: 0 | AH15: 0 | AI15: 0 | AJ15: 0 | AK15: 0 | AP15: 1
A16: 0 | B16: 0 | C16: 0 | D16: 0 | E16: 0 | F16: 0 | G16: 0 | H16: 0 | I16: 0 | J16: 1 | K16: 9 | L16: 1 | M16: 1 | N16: 1 | O16: 1 | P16: 0 | Q16: 0 | R16: 0 | S16: 1 | T16: 1 | U16: 1 | V16: 1 | W16: 9 | X16: 1 | Y16: 0 | Z16: 0 | AA16: 0 | AB16: 0 | AC16: 0 | AD16: 0 | AE16: 0 | AF16: 0 | AG16: 0 | AH16: 0 | AI16: 0 | AJ16: 0 | AK16: 0
A17: 0 | B17: 0 | C17: 0 | D17: 0 | E17: 0 | F17: 0 | G17: 0 | H17: 0 | I17: 0 | J17: 1 | K17: 9 | L17: 1 | M17: 1 | N17: 1 | O17: 1 | P17: 0 | Q17: 0 | R17: 0 | S17: 1 | T17: 1 | U17: 1 | V17: 1 | W17: 9 | X17: 1 | Y17: 0 | Z17: 0 | AA17: 0 | AB17: 0 | AC17: 0 | AD17: 0 | AE17: 0 | AF17: 0 | AG17: 0 | AH17: 0 | AI17: 0 | AJ17: 0 | AK17: 0
A18: 0 | B18: 0 | C18: 0 | D18: 0 | E18: 0 | F18: 0 | G18: 0 | H18: 0 | I18: 0 | J18: 1 | K18: 9 | L18: 0 | M18: 1 | N18: 1 | O18: 0 | P18: 0 | Q18: 0 | R18: 0 | S18: 0 | T18: 1 | U18: 1 | V18: 0 | W18: 9 | X18: 1 | Y18: 0 | Z18: 0 | AA18: 0 | AB18: 0 | AC18: 0 | AD18: 0 | AE18: 0 | AF18: 0 | AG18: 0 | AH18: 0 | AI18: 0 | AJ18: 0 | AK18: 0
A19: 0 | B19: 0 | C19: 0 | D19: 0 | E19: 0 | F19: 0 | G19: 0 | H19: 0 | I19: 1 | J19: 0 | K19: 1 | L19: 9 | M19: 0 | N19: 0 | O19: 0 | P19: 0 | Q19: 0 | R19: 0 | S19: 0 | T19: 0 | U19: 0 | V19: 9 | W19: 1 | X19: 0 | Y19: 0 | Z19: 0 | AA19: 0 | AB19: 0 | AC19: 0 | AD19: 0 | AE19: 0 | AF19: 0 | AG19: 0 | AH19: 0 | AI19: 0 | AJ19: 0 | AK19: 0
A20: 0 | B20: 0 | C20: 0 | D20: 0 | E20: 0 | F20: 0 | G20: 0 | H20: 1 | I20: 9 | J20: 1 | K20: 0 | L20: 1 | M20: 1 | N20: 1 | O20: 1 | P20: 1 | Q20: 1 | R20: 1 | S20: 1 | T20: 1 | U20: 1 | V20: 1 | W20: 0 | X20: 0 | Y20: 0 | Z20: 0 | AA20: 0 | AB20: 0 | AC20: 0 | AD20: 0 | AE20: 0 | AF20: 0 | AG20: 0 | AH20: 0 | AI20: 0 | AJ20: 0 | AK20: 0
A21: 0 | B21: 0 | C21: 0 | D21: 0 | E21: 0 | F21: 0 | G21: 0 | H21: 0 | I21: 1 | J21: 9 | K21: 1 | L21: 9 | M21: 1 | N21: 1 | O21: 10 | P21: 1 | Q21: 10 | R21: 10 | S21: 10 | T21: 1 | U21: 0 | V21: 0 | W21: 0 | X21: 0 | Y21: 0 | Z21: 0 | AA21: 0 | AB21: 0 | AC21: 0 | AD21: 0 | AE21: 0 | AF21: 0 | AG21: 0 | AH21: 0 | AI21: 0 | AJ21: 0 | AK21: 0
A22: 0 | B22: 0 | C22: 0 | D22: 0 | E22: 0 | F22: 0 | G22: 0 | H22: 0 | I22: 0 | J22: 1 | K22: 9 | L22: 1 | M22: 1 | N22: 10 | O22: 5 | P22: 1 | Q22: 5 | R22: 10 | S22: 10 | T22: 10 | U22: 1 | V22: 0 | W22: 0 | X22: 0 | Y22: 0 | Z22: 0 | AA22: 0 | AB22: 0 | AC22: 0 | AD22: 0 | AE22: 0 | AF22: 0 | AG22: 0 | AH22: 0 | AI22: 0 | AJ22: 0 | AK22: 0
A23: 0 | B23: 0 | C23: 0 | D23: 0 | E23: 0 | F23: 0 | G23: 0 | H23: 0 | I23: 1 | J23: 9 | K23: 1 | L23: 1 | M23: 10 | N23: 10 | O23: 1 | P23: 10 | Q23: 1 | R23: 5 | S23: 10 | T23: 10 | U23: 10 | V23: 1 | W23: 0 | X23: 0 | Y23: 0 | Z23: 0 | AA23: 0 | AB23: 0 | AC23: 0 | AD23: 0 | AE23: 0 | AF23: 0 | AG23: 0 | AH23: 0 | AI23: 0 | AJ23: 0 | AK23: 0
A24: 0 | B24: 0 | C24: 0 | D24: 0 | E24: 0 | F24: 0 | G24: 0 | H24: 0 | I24: 0 | J24: 1 | K24: 0 | L24: 1 | M24: 10 | N24: 5 | O24: 1 | P24: 5 | Q24: 10 | R24: 1 | S24: 5 | T24: 10 | U24: 10 | V24: 1 | W24: 0 | X24: 0 | Y24: 0 | Z24: 0 | AA24: 0 | AB24: 0 | AC24: 0 | AD24: 0 | AE24: 0 | AF24: 0 | AG24: 0 | AH24: 0 | AI24: 0 | AJ24: 0 | AK24: 0
A25: 0 | B25: 0 | C25: 0 | D25: 0 | E25: 0 | F25: 0 | G25: 0 | H25: 0 | I25: 0 | J25: 0 | K25: 0 | L25: 1 | M25: 10 | N25: 1 | O25: 10 | P25: 1 | Q25: 10 | R25: 1 | S25: 5 | T25: 10 | U25: 10 | V25: 1 | W25: 0 | X25: 0 | Y25: 0 | Z25: 0 | AA25: 0 | AB25: 0 | AC25: 0 | AD25: 0 | AE25: 0 | AF25: 0 | AG25: 0 | AH25: 0 | AI25: 0 | AJ25: 0 | AK25: 0
A26: 0 | B26: 0 | C26: 0 | D26: 0 | E26: 0 | F26: 0 | G26: 0 | H26: 0 | I26: 0 | J26: 0 | K26: 0 | L26: 1 | M26: 5 | N26: 1 | O26: 10 | P26: 1 | Q26: 5 | R26: 1 | S26: 5 | T26: 5 | U26: 10 | V26: 1 | W26: 0 | X26: 0 | Y26: 0 | Z26: 0 | AA26: 0 | AB26: 0 | AC26: 0 | AD26: 0 | AE26: 0 | AF26: 0 | AG26: 0 | AH26: 0 | AI26: 0 | AJ26: 0 | AK26: 0
A27: 0 | B27: 0 | C27: 0 | D27: 0 | E27: 0 | F27: 0 | G27: 0 | H27: 0 | I27: 0 | J27: 0 | K27: 0 | L27: 1 | M27: 5 | N27: 1 | O27: 5 | P27: 1 | Q27: 5 | R27: 10 | S27: 1 | T27: 5 | U27: 10 | V27: 1 | W27: 0 | X27: 0 | Y27: 0 | Z27: 0 | AA27: 0 | AB27: 0 | AC27: 0 | AD27: 0 | AE27: 0 | AF27: 0 | AG27: 0 | AH27: 0 | AI27: 0 | AJ27: 0 | AK27: 0
... A36: 0 | B36: 0 | C36: 0 | D36: 0 | E36: 0 | F36: 0 | G36: 0 | H36: 0 | I36: 0 | J36: 0 | K36: 0 | L36: 0 | M36: 0 | N36: 0 | O36: 0 | P36: 0 | Q36: 0 | R36: 0 | S36: 0 | T36: 0 | U36: 0 | V36: 0 | W36: 0 | X36: 0 | Y36: 0 | Z36: 0 | AA36: 0 | AB36: 0 | AC36: 0 | AD36: 0 | AE36: 0 | AF36: 0 | AG36: 0 | AH36: 0 | AI36: 0 | AJ36: 0 | AK36: 0

Sheet transpuestaC
A1: {=TRANSPOSE(HollowKnight!A1:AK36)} -> 0 | B1: 0 | C1: 0 | D1: 0 | E1: 0 | F1: 0 | G1: 0 | H1: 0 | I1: 0 | J1: 0 | K1: 0 | L1: 0 | M1: 0 | N1: 0 | O1: 0 | P1: 0 | Q1: 0 | R1: 0 | S1: 0 | T1: 0 | U1: 0 | V1: 0 | W1: 0 | X1: 0 | Y1: 0 | Z1: 0 | AA1: 0 | AB1: 0 | AC1: 0 | AD1: 0 | AE1: 0 | AF1: 0 | AG1: 0 | AH1: 0 | AI1: 0 | AJ1: 0
A2: 0 | B2: 0 | C2: 0 | D2: 0 | E2: 0 | F2: 0 | G2: 0 | H2: 0 | I2: 0 | J2: 0 | K2: 0 | L2: 0 | M2: 0 | N2: 0 | O2: 0 | P2: 0 | Q2: 0 | R2: 0 | S2: 0 | T2: 0 | U2: 0 | V2: 0 | W2: 0 | X2: 0 | Y2: 0 | Z2: 0 | AA2: 0 | AB2: 0 | AC2: 0 | AD2: 0 | AE2: 0 | AF2: 0 | AG2: 0 | AH2: 0 | AI2: 0 | AJ2: 0
A3: 0 | B3: 0 | C3: 0 | D3: 0 | E3: 0 | F3: 0 | G3: 0 | H3: 0 | I3: 0 | J3: 0 | K3: 0 | L3: 0 | M3: 0 | N3: 0 | O3: 0 | P3: 0 | Q3: 0 | R3: 0 | S3: 0 | T3: 0 | U3: 0 | V3: 0 | W3: 0 | X3: 0 | Y3: 0 | Z3: 0 | AA3: 0 | AB3: 0 | AC3: 0 | AD3: 0 | AE3: 0 | AF3: 0 | AG3: 0 | AH3: 0 | AI3: 0 | AJ3: 0
A4: 0 | B4: 0 | C4: 0 | D4: 0 | E4: 0 | F4: 0 | G4: 0 | H4: 0 | I4: 0 | J4: 0 | K4: 0 | L4: 0 | M4: 0 | N4: 0 | O4: 0 | P4: 0 | Q4: 0 | R4: 0 | S4: 0 | T4: 0 | U4: 0 | V4: 0 | W4: 0 | X4: 0 | Y4: 0 | Z4: 0 | AA4: 0 | AB4: 0 | AC4: 0 | AD4: 0 | AE4: 0 | AF4: 0 | AG4: 0 | AH4: 0 | AI4: 0 | AJ4: 0
A5: 0 | B5: 0 | C5: 0 | D5: 0 | E5: 0 | F5: 0 | G5: 0 | H5: 0 | I5: 0 | J5: 0 | K5: 0 | L5: 0 | M5: 0 | N5: 0 | O5: 0 | P5: 0 | Q5: 0 | R5: 0 | S5: 0 | T5: 0 | U5: 0 | V5: 0 | W5: 0 | X5: 0 | Y5: 0 | Z5: 0 | AA5: 0 | AB5: 0 | AC5: 0 | AD5: 0 | AE5: 0 | AF5: 0 | AG5: 0 | AH5: 0 | AI5: 0 | AJ5: 0
A6: 0 | B6: 0 | C6: 0 | D6: 0 | E6: 0 | F6: 0 | G6: 0 | H6: 0 | I6: 0 | J6: 0 | K6: 0 | L6: 0 | M6: 0 | N6: 0 | O6: 0 | P6: 0 | Q6: 0 | R6: 0 | S6: 0 | T6: 0 | U6: 0 | V6: 0 | W6: 0 | X6: 0 | Y6: 0 | Z6: 0 | AA6: 0 | AB6: 0 | AC6: 0 | AD6: 0 | AE6: 0 | AF6: 0 | AG6: 0 | AH6: 0 | AI6: 0 | AJ6: 0
A7: 0 | B7: 0 | C7: 0 | D7: 0 | E7: 0 | F7: 0 | G7: 0 | H7: 0 | I7: 0 | J7: 0 | K7: 0 | L7: 0 | M7: 0 | N7: 0 | O7: 0 | P7: 0 | Q7: 0 | R7: 0 | S7: 0 | T7: 0 | U7: 0 | V7: 0 | W7: 0 | X7: 0 | Y7: 0 | Z7: 0 | AA7: 0 | AB7: 0 | AC7: 0 | AD7: 0 | AE7: 0 | AF7: 0 | AG7: 0 | AH7: 0 | AI7: 0 | AJ7: 0
A8: 0 | B8: 0 | C8: 0 | D8: 0 | E8: 0 | F8: 0 | G8: 0 | H8: 1 | I8: 1 | J8: 1 | K8: 0 | L8: 0 | M8: 0 | N8: 0 | O8: 0 | P8: 0 | Q8: 0 | R8: 0 | S8: 0 | T8: 1 | U8: 0 | V8: 0 | W8: 0 | X8: 0 | Y8: 0 | Z8: 0 | AA8: 0 | AB8: 0 | AC8: 0 | AD8: 0 | AE8: 0 | AF8: 0 | AG8: 0 | AH8: 0 | AI8: 0 | AJ8: 0
A9: 0 | B9: 0 | C9: 0 | D9: 0 | E9: 0 | F9: 0 | G9: 1 | H9: 9 | I9: 9 | J9: 9 | K9: 1 | L9: 0 | M9: 0 | N9: 0 | O9: 0 | P9: 0 | Q9: 0 | R9: 0 | S9: 1 | T9: 9 | U9: 1 | V9: 0 | W9: 1 | X9: 0 | Y9: 0 | Z9: 0 | AA9: 0 | AB9: 0 | AC9: 0 | AD9: 0 | AE9: 0 | AF9: 0 | AG9: 0 | AH9: 0 | AI9: 0 | AJ9: 0
A10: 0 | B10: 0 | C10: 0 | D10: 0 | E10: 0 | F10: 1 | G10: 9 | H10: 0 | I10: 0 | J10: 0 | K10: 9 | L10: 1 | M10: 1 | N10: 1 | O10: 1 | P10: 1 | Q10: 1 | R10: 1 | S10: 0 | T10: 1 | U10: 9 | V10: 1 | W10: 9 | X10: 1 | Y10: 0 | Z10: 0 | AA10: 0 | AB10: 0 | AC10: 0 | AD10: 0 | AE10: 0 | AF10: 0 | AG10: 0 | AH10: 0 | AI10: 0 | AJ10: 0
A11: 0 | B11: 0 | C11: 0 | D11: 0 | E11: 1 | F11: 9 | G11: 0 | H11: 1 | I11: 1 | J11: 0 | K11: 0 | L11: 9 | M11: 9 | N11: 9 | O11: 9 | P11: 9 | Q11: 9 | R11: 9 | S11: 1 | T11: 0 | U11: 1 | V11: 9 | W11: 1 | X11: 0 | Y11: 0 | Z11: 0 | AA11: 0 | AB11: 0 | AC11: 0 | AD11: 0 | AE11: 0 | AF11: 0 | AG11: 0 | AH11: 0 | AI11: 0 | AJ11: 0
A12: 0 | B12: 0 | C12: 0 | D12: 1 | E12: 9 | F12: 0 | G12: 1 | H12: 0 | I12: 0 | J12: 1 | K12: 0 | L12: 0 | M12: 0 | N12: 0 | O12: 0 | P12: 1 | Q12: 1 | R12: 0 | S12: 9 | T12: 1 | U12: 9 | V12: 1 | W12: 1 | X12: 1 | Y12: 1 | Z12: 1 | AA12: 1 | AB12: 1 | AC12: 1 | AD12: 1 | AE12: 1 | AF12: 0 | AG12: 0 | AH12: 0 | AI12: 0 | AJ12: 0
A13: 0 | B13: 0 | C13: 0 | D13: 1 | E13: 1 | F13: 1 | G13: 0 | H13: 0 | I13: 0 | J13: 1 | K13: 0 | L13: 0 | M13: 0 | N13: 0 | O13: 1 | P13: 1 | Q13: 1 | R13: 1 | S13: 0 | T13: 1 | U13: 1 | V13: 1 | W13: 10 | X13: 10 | Y13: 10 | Z13: 5 | AA13: 5 | AB13: 1 | AC13: 5 | AD13: 1 | AE13: 1 | AF13: 1 | AG13: 0 | AH13: 0 | AI13: 0 | AJ13: 0
... A37: 0 | B37: 0 | C37: 0 | D37: 0 | E37: 0 | F37: 0 | G37: 0 | H37: 0 | I37: 0 | J37: 0 | K37: 0 | L37: 0 | M37: 0 | N37: 0 | O37: 0 | P37: 0 | Q37: 0 | R37: 0 | S37: 0 | T37: 0 | U37: 0 | V37: 0 | W37: 0 | X37: 0 | Y37: 0 | Z37: 0 | AA37: 0 | AB37: 0 | AC37: 0 | AD37: 0 | AE37: 0 | AF37: 0 | AG37: 0 | AH37: 0 | AI37: 0 | AJ37: 0

Sheet Snoopy
A1: 8 | B1: 8 | C1: 8 | D1: 8 | E1: 8 | F1: 8 | G1: 8 | H1: 8 | I1: 8 | J1: 8 | K1: 8 | L1: 8 | M1: 8 | N1: 8 | O1: 8 | P1: 8 | Q1: 8 | R1: 8 | S1: 8 | T1: 8 | U1: 8 | V1: 8 | W1: 8 | X1: 8 | Y1: 8 | Z1: 8 | AA1: 8 | AB1: 8 | AC1: 8 | AD1: 8 | AE1: 8 | AF1: 8 | AG1: 8 | AH1: 8 | AI1: 8 | AJ1: 8
A2: 8 | B2: 8 | C2: 8 | D2: 8 | E2: 8 | F2: 8 | G2: 8 | H2: 8 | I2: 8 | J2: 8 | K2: 8 | L2: 8 | M2: 8 | N2: 8 | O2: 8 | P2: 8 | Q2: 8 | R2: 8 | S2: 8 | T2: 8 | U2: 8 | V2: 8 | W2: 8 | X2: 8 | Y2: 8 | Z2: 8 | AA2: 8 | AB2: 8 | AC2: 8 | AD2: 8 | AE2: 8 | AF2: 8 | AG2: 8 | AH2: 8 | AI2: 8 | AJ2: 8
A3: 8 | B3: 8 | C3: 8 | D3: 8 | E3: 8 | F3: 8 | G3: 8 | H3: 8 | I3: 1 | J3: 1 | K3: 1 | L3: 1 | M3: 1 | N3: 8 | O3: 8 | P3: 8 | Q3: 8 | R3: 8 | S3: 8 | T3: 8 | U3: 8 | V3: 8 | W3: 8 | X3: 8 | Y3: 8 | Z3: 8 | AA3: 8 | AB3: 8 | AC3: 8 | AD3: 8 | AE3: 8 | AF3: 8 | AG3: 8 | AH3: 8 | AI3: 8 | AJ3: 8
A4: 8 | B4: 8 | C4: 8 | D4: 8 | E4: 8 | F4: 8 | G4: 8 | H4: 1 | I4: 0 | J4: 0 | K4: 0 | L4: 0 | M4: 0 | N4: 1 | O4: 8 | P4: 8 | Q4: 8 | R4: 8 | S4: 8 | T4: 8 | U4: 8 | V4: 8 | W4: 8 | X4: 8 | Y4: 8 | Z4: 8 | AA4: 8 | AB4: 8 | AC4: 8 | AD4: 8 | AE4: 8 | AF4: 8 | AG4: 8 | AH4: 8 | AI4: 8 | AJ4: 8
A5: 8 | B5: 8 | C5: 8 | D5: 8 | E5: 8 | F5: 8 | G5: 1 | H5: 0 | I5: 0 | J5: 0 | K5: 0 | L5: 0 | M5: 0 | N5: 0 | O5: 1 | P5: 8 | Q5: 8 | R5: 8 | S5: 8 | T5: 8 | U5: 8 | V5: 8 | W5: 8 | X5: 8 | Y5: 8 | Z5: 8 | AA5: 8 | AB5: 8 | AC5: 8 | AD5: 8 | AE5: 8 | AF5: 8 | AG5: 8 | AH5: 8 | AI5: 8 | AJ5: 8
A6: 8 | B6: 8 | C6: 8 | D6: 8 | E6: 8 | F6: 1 | G6: 0 | H6: 0 | I6: 0 | J6: 0 | K6: 0 | L6: 0 | M6: 0 | N6: 0 | O6: 0 | P6: 1 | Q6: 1 | R6: 1 | S6: 8 | T6: 8 | U6: 8 | V6: 8 | W6: 8 | X6: 8 | Y6: 8 | Z6: 8 | AA6: 8 | AB6: 8 | AC6: 8 | AD6: 8 | AE6: 8 | AF6: 8 | AG6: 8 | AH6: 8 | AI6: 8 | AJ6: 8
A7: 8 | B7: 8 | C7: 8 | D7: 8 | E7: 8 | F7: 1 | G7: 1 | H7: 0 | I7: 1 | J7: 0 | K7: 0 | L7: 0 | M7: 0 | N7: 1 | O7: 0 | P7: 0 | Q7: 0 | R7: 0 | S7: 1 | T7: 8 | U7: 8 | V7: 8 | W7: 8 | X7: 8 | Y7: 8 | Z7: 8 | AA7: 8 | AB7: 8 | AC7: 8 | AD7: 8 | AE7: 8 | AF7: 8 | AG7: 8 | AH7: 8 | AI7: 8 | AJ7: 8
A8: 8 | B8: 8 | C8: 8 | D8: 8 | E8: 1 | F8: 0 | G8: 1 | H8: 1 | I8: 0 | J8: 1 | K8: 0 | L8: 0 | M8: 0 | N8: 1 | O8: 0 | P8: 0 | Q8: 0 | R8: 0 | S8: 0 | T8: 1 | U8: 1 | V8: 8 | W8: 8 | X8: 8 | Y8: 8 | Z8: 8 | AA8: 8 | AB8: 8 | AC8: 8 | AD8: 8 | AE8: 8 | AF8: 8 | AG8: 8 | AH8: 8 | AI8: 8 | AJ8: 8
A9: 8 | B9: 8 | C9: 8 | D9: 8 | E9: 1 | F9: 1 | G9: 1 | H9: 1 | I9: 0 | J9: 1 | K9: 0 | L9: 0 | M9: 0 | N9: 0 | O9: 0 | P9: 0 | Q9: 0 | R9: 0 | S9: 0 | T9: 1 | U9: 1 | V9: 8 | W9: 8 | X9: 8 | Y9: 8 | Z9: 8 | AA9: 8 | AB9: 8 | AC9: 8 | AD9: 8 | AE9: 8 | AF9: 8 | AG9: 8 | AH9: 8 | AI9: 8 | AJ9: 8
A10: 8 | B10: 8 | C10: 8 | D10: 8 | E10: 1 | F10: 1 | G10: 1 | H10: 1 | I10: 0 | J10: 1 | K10: 0 | L10: 0 | M10: 0 | N10: 0 | O10: 0 | P10: 0 | Q10: 0 | R10: 0 | S10: 0 | T10: 1 | U10: 8 | V10: 8 | W10: 8 | X10: 8 | Y10: 8 | Z10: 8 | AA10: 8 | AB10: 8 | AC10: 8 | AD10: 8 | AE10: 8 | AF10: 8 | AG10: 8 | AH10: 8 | AI10: 8 | AJ10: 8
A11: 8 | B11: 8 | C11: 8 | D11: 8 | E11: 1 | F11: 1 | G11: 1 | H11: 1 | I11: 0 | J11: 1 | K11: 0 | L11: 0 | M11: 0 | N11: 0 | O11: 0 | P11: 0 | Q11: 0 | R11: 0 | S11: 1 | T11: 8 | U11: 8 | V11: 8 | W11: 8 | X11: 8 | Y11: 8 | Z11: 8 | AA11: 8 | AB11: 8 | AC11: 8 | AD11: 8 | AE11: 8 | AF11: 8 | AG11: 8 | AH11: 8 | AI11: 8 | AJ11: 8
A12: 8 | B12: 8 | C12: 8 | D12: 8 | E12: 1 | F12: 1 | G12: 1 | H12: 1 | I12: 0 | J12: 1 | K12: 0 | L12: 0 | M12: 0 | N12: 0 | O12: 0 | P12: 0 | Q12: 1 | R12: 1 | S12: 8 | T12: 8 | U12: 8 | V12: 8 | W12: 8 | X12: 8 | Y12: 8 | Z12: 8 | AA12: 8 | AB12: 8 | AC12: 8 | AD12: 8 | AE12: 8 | AF12: 8 | AG12: 8 | AH12: 8 | AI12: 8 | AJ12: 8
... A36: 8 | B36: 8 | C36: 8 | D36: 8 | E36: 8 | F36: 8 | G36: 8 | H36: 8 | I36: 8 | J36: 8 | K36: 8 | L36: 8 | M36: 8 | N36: 8 | O36: 8 | P36: 8 | Q36: 8 | R36: 8 | S36: 8 | T36: 8 | U36: 8 | V36: 8 | W36: 8 | X36: 8 | Y36: 8 | Z36: 8 | AA36: 8 | AB36: 8 | AC36: 8 | AD36: 8 | AE36: 8 | AF36: 8 | AG36: 8 | AH36: 8 | AI36: 8 | AJ36: 8

Sheet transpuestaD
A1: {=TRANSPOSE(Snoopy!A1:AK36)} -> 8 | B1: 8 | C1: 8 | D1: 8 | E1: 8 | F1: 8 | G1: 8 | H1: 8 | I1: 8 | J1: 8 | K1: 8 | L1: 8 | M1: 8 | N1: 8 | O1: 8 | P1: 8 | Q1: 8 | R1: 8 | S1: 8 | T1: 8 | U1: 8 | V1: 8 | W1: 8 | X1: 8 | Y1: 8 | Z1: 8 | AA1: 8 | AB1: 8 | AC1: 8 | AD1: 8 | AE1: 8 | AF1: 8 | AG1: 8 | AH1: 8 | AI1: 8 | AJ1: 8
A2: 8 | B2: 8 | C2: 8 | D2: 8 | E2: 8 | F2: 8 | G2: 8 | H2: 8 | I2: 8 | J2: 8 | K2: 8 | L2: 8 | M2: 8 | N2: 8 | O2: 8 | P2: 8 | Q2: 8 | R2: 8 | S2: 8 | T2: 8 | U2: 8 | V2: 8 | W2: 8 | X2: 8 | Y2: 8 | Z2: 8 | AA2: 8 | AB2: 8 | AC2: 8 | AD2: 8 | AE2: 8 | AF2: 8 | AG2: 8 | AH2: 8 | AI2: 8 | AJ2: 8
A3: 8 | B3: 8 | C3: 8 | D3: 8 | E3: 8 | F3: 8 | G3: 8 | H3: 8 | I3: 8 | J3: 8 | K3: 8 | L3: 8 | M3: 8 | N3: 8 | O3: 8 | P3: 8 | Q3: 8 | R3: 8 | S3: 8 | T3: 8 | U3: 8 | V3: 8 | W3: 8 | X3: 8 | Y3: 8 | Z3: 8 | AA3: 8 | AB3: 8 | AC3: 8 | AD3: 8 | AE3: 8 | AF3: 8 | AG3: 8 | AH3: 8 | AI3: 8 | AJ3: 8
A4: 8 | B4: 8 | C4: 8 | D4: 8 | E4: 8 | F4: 8 | G4: 8 | H4: 8 | I4: 8 | J4: 8 | K4: 8 | L4: 8 | M4: 8 | N4: 8 | O4: 8 | P4: 8 | Q4: 8 | R4: 8 | S4: 8 | T4: 8 | U4: 8 | V4: 8 | W4: 8 | X4: 8 | Y4: 8 | Z4: 8 | AA4: 8 | AB4: 8 | AC4: 8 | AD4: 8 | AE4: 8 | AF4: 8 | AG4: 8 | AH4: 8 | AI4: 8 | AJ4: 8
A5: 8 | B5: 8 | C5: 8 | D5: 8 | E5: 8 | F5: 8 | G5: 8 | H5: 1 | I5: 1 | J5: 1 | K5: 1 | L5: 1 | M5: 8 | N5: 8 | O5: 8 | P5: 8 | Q5: 8 | R5: 8 | S5: 8 | T5: 8 | U5: 8 | V5: 8 | W5: 8 | X5: 8 | Y5: 8 | Z5: 8 | AA5: 8 | AB5: 8 | AC5: 8 | AD5: 8 | AE5: 8 | AF5: 8 | AG5: 8 | AH5: 8 | AI5: 8 | AJ5: 8
A6: 8 | B6: 8 | C6: 8 | D6: 8 | E6: 8 | F6: 1 | G6: 1 | H6: 0 | I6: 1 | J6: 1 | K6: 1 | L6: 1 | M6: 1 | N6: 8 | O6: 8 | P6: 8 | Q6: 8 | R6: 8 | S6: 8 | T6: 8 | U6: 8 | V6: 8 | W6: 8 | X6: 8 | Y6: 8 | Z6: 8 | AA6: 8 | AB6: 8 | AC6: 8 | AD6: 8 | AE6: 8 | AF6: 8 | AG6: 8 | AH6: 8 | AI6: 8 | AJ6: 8
A7: 8 | B7: 8 | C7: 8 | D7: 8 | E7: 1 | F7: 0 | G7: 1 | H7: 1 | I7: 1 | J7: 1 | K7: 1 | L7: 1 | M7: 1 | N7: 1 | O7: 8 | P7: 8 | Q7: 8 | R7: 8 | S7: 8 | T7: 8 | U7: 8 | V7: 8 | W7: 8 | X7: 8 | Y7: 8 | Z7: 8 | AA7: 8 | AB7: 8 | AC7: 8 | AD7: 8 | AE7: 8 | AF7: 8 | AG7: 8 | AH7: 8 | AI7: 8 | AJ7: 8
A8: 8 | B8: 8 | C8: 8 | D8: 1 | E8: 0 | F8: 0 | G8: 0 | H8: 1 | I8: 1 | J8: 1 | K8: 1 | L8: 1 | M8: 0 | N8: 1 | O8: 8 | P8: 8 | Q8: 8 | R8: 8 | S8: 8 | T8: 8 | U8: 8 | V8: 8 | W8: 8 | X8: 8 | Y8: 8 | Z8: 8 | AA8: 8 | AB8: 8 | AC8: 8 | AD8: 8 | AE8: 8 | AF8: 8 | AG8: 8 | AH8: 8 | AI8: 8 | AJ8: 8
A9: 8 | B9: 8 | C9: 1 | D9: 0 | E9: 0 | F9: 0 | G9: 1 | H9: 0 | I9: 0 | J9: 0 | K9: 0 | L9: 0 | M9: 1 | N9: 8 | O9: 8 | P9: 8 | Q9: 8 | R9: 8 | S9: 8 | T9: 8 | U9: 8 | V9: 1 | W9: 8 | X9: 8 | Y9: 8 | Z9: 8 | AA9: 8 | AB9: 8 | AC9: 8 | AD9: 8 | AE9: 8 | AF9: 8 | AG9: 8 | AH9: 8 | AI9: 8 | AJ9: 8
A10: 8 | B10: 8 | C10: 1 | D10: 0 | E10: 0 | F10: 0 | G10: 0 | H10: 1 | I10: 1 | J10: 1 | K10: 1 | L10: 1 | M10: 8 | N10: 8 | O10: 8 | P10: 8 | Q10: 8 | R10: 1 | S10: 1 | T10: 8 | U10: 1 | V10: 0 | W10: 1 | X10: 8 | Y10: 1 | Z10: 1 | AA10: 8 | AB10: 8 | AC10: 8 | AD10: 8 | AE10: 8 | AF10: 8 | AG10: 8 | AH10: 8 | AI10: 8 | AJ10: 8
A11: 8 | B11: 8 | C11: 1 | D11: 0 | E11: 0 | F11: 0 | G11: 0 | H11: 0 | I11: 0 | J11: 0 | K11: 0 | L11: 0 | M11: 1 | N11: 8 | O11: 1 | P11: 1 | Q11: 1 | R11: 0 | S11: 0 | T11: 1 | U11: 1 | V11: 0 | W11: 1 | X11: 1 | Y11: 0 | Z11: 1 | AA11: 8 | AB11: 8 | AC11: 8 | AD11: 8 | AE11: 8 | AF11: 8 | AG11: 8 | AH11: 8 | AI11: 8 | AJ11: 8
A12: 8 | B12: 8 | C12: 1 | D12: 0 | E12: 0 | F12: 0 | G12: 0 | H12: 0 | I12: 0 | J12: 0 | K12: 0 | L12: 0 | M12: 0 | N12: 7 | O12: 0 | P12: 0 | Q12: 0 | R12: 0 | S12: 0 | T12: 1 | U12: 0 | V12: 0 | W12: 1 | X12: 0 | Y12: 0 | Z12: 1 | AA12: 8 | AB12: 8 | AC12: 8 | AD12: 8 | AE12: 8 | AF12: 8 | AG12: 8 | AH12: 8 | AI12: 8 | AJ12: 8
A13: 8 | B13: 8 | C13: 1 | D13: 0 | E13: 0 | F13: 0 | G13: 0 | H13: 0 | I13: 0 | J13: 0 | K13: 0 | L13: 0 | M13: 0 | N13: 7 | O13: 0 | P13: 1 | Q13: 1 | R13: 1 | S13: 1 | T13: 0 | U13: 0 | V13: 0 | W13: 0 | X13: 0 | Y13: 0 | Z13: 1 | AA13: 8 | AB13: 8 | AC13: 8 | AD13: 8 | AE13: 8 | AF13: 8 | AG13: 8 | AH13: 8 | AI13: 8 | AJ13: 8
... A37: 0 | B37: 0 | C37: 0 | D37: 0 | E37: 0 | F37: 0 | G37: 0 | H37: 0 | I37: 0 | J37: 0 | K37: 0 | L37: 0 | M37: 0 | N37: 0 | O37: 0 | P37: 0 | Q37: 0 | R37: 0 | S37: 0 | T37: 0 | U37: 0 | V37: 0 | W37: 0 | X37: 0 | Y37: 0 | Z37: 0 | AA37: 0 | AB37: 0 | AC37: 0 | AD37: 0 | AE37: 0 | AF37: 0 | AG37: 0 | AH37: 0 | AI37: 0 | AJ37: 0

Sheet Foxy
A1: 0 | B1: 0 | C1: 0 | D1: 0 | E1: 0 | F1: 0 | G1: 0 | H1: 0 | I1: 0 | J1: 0 | K1: 0 | L1: 0 | M1: 0 | N1: 0 | O1: 0 | P1: 0 | Q1: 0 | R1: 0 | S1: 0 | T1: 0 | U1: 0 | V1: 0 | W1: 0 | X1: 0 | Y1: 0 | Z1: 0 | AA1: 0 | AB1: 0 | AC1: 0 | AD1: 0 | AE1: 0 | AF1: 0 | AG1: 0 | AH1: 0 | AI1: 0 | AJ1: 0 | AK1: 0
A2: 0 | B2: 0 | C2: 0 | D2: 0 | E2: 0 | F2: 0 | G2: 0 | H2: 0 | I2: 0 | J2: 0 | K2: 0 | L2: 0 | M2: 0 | N2: 0 | O2: 0 | P2: 0 | Q2: 0 | R2: 0 | S2: 0 | T2: 0 | U2: 0 | V2: 0 | W2: 0 | X2: 0 | Y2: 0 | Z2: 0 | AA2: 0 | AB2: 0 | AC2: 0 | AD2: 0 | AE2: 0 | AF2: 0 | AG2: 0 | AH2: 0 | AI2: 0 | AJ2: 0 | AK2: 0
A3: 0 | B3: 0 | C3: 0 | D3: 1 | E3: 1 | F3: 1 | G3: 1 | H3: 0 | I3: 0 | J3: 0 | K3: 0 | L3: 0 | M3: 0 | N3: 0 | O3: 0 | P3: 0 | Q3: 0 | R3: 0 | S3: 0 | T3: 0 | U3: 0 | V3: 0 | W3: 1 | X3: 1 | Y3: 1 | Z3: 1 | AA3: 0 | AB3: 0 | AC3: 0 | AD3: 0 | AE3: 0 | AF3: 0 | AG3: 0 | AH3: 0 | AI3: 0 | AJ3: 0 | AK3: 0
A4: 0 | B4: 0 | C4: 0 | D4: 1 | E4: 11 | F4: 11 | G4: 11 | H4: 1 | I4: 1 | J4: 0 | K4: 0 | L4: 0 | M4: 0 | N4: 0 | O4: 1 | P4: 0 | Q4: 0 | R4: 0 | S4: 0 | T4: 0 | U4: 1 | V4: 1 | W4: 11 | X4: 11 | Y4: 11 | Z4: 1 | AA4: 0 | AB4: 0 | AC4: 0 | AD4: 0 | AE4: 0 | AF4: 0 | AG4: 0 | AH4: 0 | AI4: 0 | AJ4: 0 | AK4: 0
A5: 0 | B5: 0 | C5: 0 | D5: 1 | E5: 11 | F5: 12 | G5: 12 | H5: 11 | I5: 11 | J5: 1 | K5: 0 | L5: 1 | M5: 1 | N5: 1 | O5: 11 | P5: 1 | Q5: 1 | R5: 1 | S5: 0 | T5: 1 | U5: 11 | V5: 11 | W5: 12 | X5: 12 | Y5: 11 | Z5: 1 | AA5: 0 | AB5: 0 | AC5: 0 | AD5: 0 | AE5: 0 | AF5: 0 | AG5: 0 | AH5: 0 | AI5: 0 | AJ5: 0 | AK5: 0
A6: 0 | B6: 0 | C6: 0 | D6: 1 | E6: 11 | F6: 12 | G6: 12 | H6: 12 | I6: 12 | J6: 11 | K6: 1 | L6: 1 | M6: 11 | N6: 1 | O6: 11 | P6: 1 | Q6: 11 | R6: 1 | S6: 1 | T6: 11 | U6: 12 | V6: 12 | W6: 12 | X6: 12 | Y6: 11 | Z6: 1 | AA6: 0 | AB6: 0 | AC6: 0 | AD6: 0 | AE6: 0 | AF6: 0 | AG6: 0 | AH6: 0 | AI6: 0 | AJ6: 0 | AK6: 0
A7: 0 | B7: 0 | C7: 0 | D7: 0 | E7: 1 | F7: 11 | G7: 12 | H7: 12 | I7: 12 | J7: 11 | K7: 1 | L7: 1 | M7: 1 | N7: 11 | O7: 11 | P7: 11 | Q7: 1 | R7: 1 | S7: 1 | T7: 11 | U7: 12 | V7: 12 | W7: 12 | X7: 11 | Y7: 1 | Z7: 0 | AA7: 0 | AB7: 0 | AC7: 0 | AD7: 0 | AE7: 0 | AF7: 0 | AG7: 0 | AH7: 0 | AI7: 0 | AJ7: 0 | AK7: 0
A8: 0 | B8: 0 | C8: 0 | D8: 0 | E8: 1 | F8: 11 | G8: 12 | H8: 12 | I8: 12 | J8: 11 | K8: 1 | L8: 1 | M8: 1 | N8: 1 | O8: 1 | P8: 1 | Q8: 1 | R8: 1 | S8: 1 | T8: 11 | U8: 12 | V8: 12 | W8: 12 | X8: 11 | Y8: 1 | Z8: 0 | AA8: 0 | AB8: 0 | AC8: 0 | AD8: 0 | AE8: 0 | AF8: 0 | AG8: 0 | AH8: 0 | AI8: 0 | AJ8: 0 | AK8: 0
A9: 0 | B9: 0 | C9: 0 | D9: 0 | E9: 0 | F9: 1 | G9: 11 | H9: 11 | I9: 11 | J9: 11 | K9: 1 | L9: 11 | M9: 11 | N9: 11 | O9: 11 | P9: 11 | Q9: 11 | R9: 11 | S9: 1 | T9: 11 | U9: 11 | V9: 11 | W9: 11 | X9: 1 | Y9: 0 | Z9: 0 | AA9: 0 | AB9: 0 | AC9: 0 | AD9: 0 | AE9: 0 | AF9: 0 | AG9: 0 | AH9: 0 | AI9: 0 | AJ9: 0 | AK9: 0
A10: 0 | B10: 0 | C10: 0 | D10: 0 | E10: 0 | F10: 0 | G10: 1 | H10: 1 | I10: 1 | J10: 1 | K10: 11 | L10: 11 | M10: 11 | N10: 11 | O10: 11 | P10: 11 | Q10: 11 | R10: 11 | S10: 11 | T10: 1 | U10: 1 | V10: 1 | W10: 1 | X10: 0 | Y10: 0 | Z10: 0 | AA10: 0 | AB10: 0 | AC10: 0 | AD10: 0 | AE10: 0 | AF10: 0 | AG10: 0 | AH10: 0 | AI10: 0 | AJ10: 0 | AK10: 0
A11: 0 | B11: 0 | C11: 0 | D11: 0 | E11: 0 | F11: 0 | G11: 0 | H11: 0 | I11: 1 | J11: 11 | K11: 11 | L11: 12 | M11: 12 | N11: 11 | O11: 11 | P11: 11 | Q11: 12 | R11: 12 | S11: 11 | T11: 11 | U11: 1 | V11: 0 | W11: 0 | X11: 0 | Y11: 0 | Z11: 0 | AA11: 0 | AB11: 0 | AC11: 0 | AD11: 0 | AE11: 0 | AF11: 0 | AG11: 0 | AH11: 0 | AI11: 0 | AJ11: 0 | AK11: 0
A12: 0 | B12: 0 | C12: 0 | D12: 0 | E12: 0 | F12: 0 | G12: 0 | H12: 0 | I12: 1 | J12: 11 | K12: 11 | L12: 11 | M12: 11 | N12: 11 | O12: 11 | P12: 11 | Q12: 11 | R12: 11 | S12: 11 | T12: 11 | U12: 1 | V12: 0 | W12: 0 | X12: 0 | Y12: 0 | Z12: 0 | AA12: 0 | AB12: 0 | AC12: 0 | AD12: 0 | AE12: 0 | AF12: 0 | AG12: 0 | AH12: 0 | AI12: 0 | AJ12: 0 | AK12: 0
... A36: 0 | B36: 0 | C36: 0 | D36: 0 | E36: 0 | F36: 0 | G36: 0 | H36: 0 | I36: 0 | J36: 0 | K36: 0 | L36: 0 | M36: 0 | N36: 0 | O36: 0 | P36: 0 | Q36: 0 | R36: 0 | S36: 0 | T36: 0 | U36: 0 | V36: 0 | W36: 0 | X36: 0 | Y36: 0 | Z36: 0 | AA36: 0 | AB36: 0 | AC36: 0 | AD36: 0 | AE36: 0 | AF36: 0 | AG36: 0 | AH36: 0 | AI36: 0 | AJ36: 0 | AK36: 0

Sheet transpuestaE
A1: {=TRANSPOSE(Foxy!A1:AK36)} -> 0 | B1: 0 | C1: 0 | D1: 0 | E1: 0 | F1: 0 | G1: 0 | H1: 0 | I1: 0 | J1: 0 | K1: 0 | L1: 0 | M1: 0 | N1: 0 | O1: 0 | P1: 0 | Q1: 0 | R1: 0 | S1: 0 | T1: 0 | U1: 0 | V1: 0 | W1: 0 | X1: 0 | Y1: 0 | Z1: 0 | AA1: 0 | AB1: 0 | AC1: 0 | AD1: 0 | AE1: 0 | AF1: 0 | AG1: 0 | AH1: 0 | AI1: 0 | AJ1: 0
A2: 0 | B2: 0 | C2: 0 | D2: 0 | E2: 0 | F2: 0 | G2: 0 | H2: 0 | I2: 0 | J2: 0 | K2: 0 | L2: 0 | M2: 0 | N2: 0 | O2: 0 | P2: 0 | Q2: 0 | R2: 0 | S2: 0 | T2: 0 | U2: 0 | V2: 0 | W2: 0 | X2: 0 | Y2: 0 | Z2: 0 | AA2: 0 | AB2: 0 | AC2: 0 | AD2: 0 | AE2: 0 | AF2: 0 | AG2: 0 | AH2: 0 | AI2: 0 | AJ2: 0
A3: 0 | B3: 0 | C3: 0 | D3: 0 | E3: 0 | F3: 0 | G3: 0 | H3: 0 | I3: 0 | J3: 0 | K3: 0 | L3: 0 | M3: 0 | N3: 0 | O3: 0 | P3: 0 | Q3: 0 | R3: 0 | S3: 0 | T3: 0 | U3: 0 | V3: 0 | W3: 0 | X3: 0 | Y3: 0 | Z3: 0 | AA3: 0 | AB3: 0 | AC3: 0 | AD3: 0 | AE3: 0 | AF3: 0 | AG3: 0 | AH3: 0 | AI3: 0 | AJ3: 0
A4: 0 | B4: 0 | C4: 1 | D4: 1 | E4: 1 | F4: 1 | G4: 0 | H4: 0 | I4: 0 | J4: 0 | K4: 0 | L4: 0 | M4: 0 | N4: 0 | O4: 0 | P4: 0 | Q4: 0 | R4: 0 | S4: 0 | T4: 0 | U4: 0 | V4: 0 | W4: 0 | X4: 0 | Y4: 0 | Z4: 0 | AA4: 0 | AB4: 0 | AC4: 0 | AD4: 0 | AE4: 0 | AF4: 0 | AG4: 0 | AH4: 0 | AI4: 0 | AJ4: 0
A5: 0 | B5: 0 | C5: 1 | D5: 11 | E5: 11 | F5: 11 | G5: 1 | H5: 1 | I5: 0 | J5: 0 | K5: 0 | L5: 0 | M5: 0 | N5: 0 | O5: 0 | P5: 1 | Q5: 0 | R5: 0 | S5: 0 | T5: 0 | U5: 0 | V5: 0 | W5: 0 | X5: 0 | Y5: 0 | Z5: 0 | AA5: 0 | AB5: 0 | AC5: 0 | AD5: 0 | AE5: 0 | AF5: 0 | AG5: 0 | AH5: 0 | AI5: 0 | AJ5: 0
A6: 0 | B6: 0 | C6: 1 | D6: 11 | E6: 12 | F6: 12 | G6: 11 | H6: 11 | I6: 1 | J6: 0 | K6: 0 | L6: 0 | M6: 0 | N6: 0 | O6: 1 | P6: 11 | Q6: 1 | R6: 0 | S6: 0 | T6: 0 | U6: 0 | V6: 0 | W6: 0 | X6: 0 | Y6: 0 | Z6: 0 | AA6: 0 | AB6: 0 | AC6: 0 | AD6: 0 | AE6: 0 | AF6: 0 | AG6: 0 | AH6: 0 | AI6: 0 | AJ6: 0
A7: 0 | B7: 0 | C7: 1 | D7: 11 | E7: 12 | F7: 12 | G7: 12 | H7: 12 | I7: 11 | J7: 1 | K7: 0 | L7: 0 | M7: 0 | N7: 1 | O7: 1 | P7: 11 | Q7: 1 | R7: 0 | S7: 0 | T7: 0 | U7: 0 | V7: 0 | W7: 0 | X7: 0 | Y7: 0 | Z7: 0 | AA7: 0 | AB7: 0 | AC7: 0 | AD7: 0 | AE7: 0 | AF7: 0 | AG7: 0 | AH7: 0 | AI7: 0 | AJ7: 0
A8: 0 | B8: 0 | C8: 0 | D8: 1 | E8: 11 | F8: 12 | G8: 12 | H8: 12 | I8: 11 | J8: 1 | K8: 0 | L8: 0 | M8: 1 | N8: 11 | O8: 1 | P8: 11 | Q8: 11 | R8: 1 | S8: 0 | T8: 0 | U8: 0 | V8: 0 | W8: 0 | X8: 0 | Y8: 0 | Z8: 0 | AA8: 0 | AB8: 0 | AC8: 0 | AD8: 0 | AE8: 0 | AF8: 0 | AG8: 0 | AH8: 0 | AI8: 0 | AJ8: 0
A9: 0 | B9: 0 | C9: 0 | D9: 1 | E9: 11 | F9: 12 | G9: 12 | H9: 12 | I9: 11 | J9: 1 | K9: 1 | L9: 1 | M9: 1 | N9: 11 | O9: 11 | P9: 11 | Q9: 11 | R9: 1 | S9: 1 | T9: 1 | U9: 0 | V9: 0 | W9: 0 | X9: 0 | Y9: 0 | Z9: 0 | AA9: 0 | AB9: 0 | AC9: 0 | AD9: 0 | AE9: 0 | AF9: 0 | AG9: 0 | AH9: 0 | AI9: 0 | AJ9: 0
A10: 0 | B10: 0 | C10: 0 | D10: 0 | E10: 1 | F10: 11 | G10: 11 | H10: 11 | I10: 11 | J10: 1 | K10: 11 | L10: 11 | M10: 1 | N10: 11 | O10: 11 | P10: 11 | Q10: 11 | R10: 1 | S10: 1 | T10: 11 | U10: 1 | V10: 1 | W10: 0 | X10: 0 | Y10: 0 | Z10: 0 | AA10: 0 | AB10: 0 | AC10: 0 | AD10: 0 | AE10: 0 | AF10: 0 | AG10: 0 | AH10: 0 | AI10: 0 | AJ10: 0
A11: 0 | B11: 0 | C11: 0 | D11: 0 | E11: 0 | F11: 1 | G11: 1 | H11: 1 | I11: 1 | J11: 11 | K11: 11 | L11: 11 | M11: 11 | N11: 1 | O11: 1 | P11: 11 | Q11: 1 | R11: 1 | S11: 1 | T11: 1 | U11: 11 | V11: 11 | W11: 1 | X11: 1 | Y11: 0 | Z11: 0 | AA11: 0 | AB11: 0 | AC11: 0 | AD11: 0 | AE11: 0 | AF11: 0 | AG11: 0 | AH11: 0 | AI11: 0 | AJ11: 0
A12: 0 | B12: 0 | C12: 0 | D12: 0 | E12: 1 | F12: 1 | G12: 1 | H12: 1 | I12: 11 | J12: 11 | K12: 12 | L12: 11 | M12: 1 | N12: 1 | O12: 1 | P12: 1 | Q12: 13 | R12: 13 | S12: 13 | T12: 0 | U12: 1 | V12: 1 | W12: 11 | X12: 1 | Y12: 1 | Z12: 0 | AA12: 0 | AB12: 0 | AC12: 0 | AD12: 0 | AE12: 0 | AF12: 0 | AG12: 0 | AH12: 0 | AI12: 0 | AJ12: 0
A13: 0 | B13: 0 | C13: 0 | D13: 0 | E13: 1 | F13: 11 | G13: 1 | H13: 1 | I13: 11 | J13: 11 | K13: 12 | L13: 11 | M13: 1 | N13: 1 | O13: 1 | P13: 1 | Q13: 13 | R13: 13 | S13: 13 | T13: 1 | U13: 1 | V13: 0 | W13: 1 | X13: 11 | Y13: 1 | Z13: 0 | AA13: 0 | AB13: 0 | AC13: 0 | AD13: 0 | AE13: 0 | AF13: 0 | AG13: 0 | AH13: 0 | AI13: 0 | AJ13: 0
... A37: 0 | B37: 0 | C37: 0 | D37: 0 | E37: 0 | F37: 0 | G37: 0 | H37: 0 | I37: 0 | J37: 0 | K37: 0 | L37: 0 | M37: 0 | N37: 0 | O37: 0 | P37: 0 | Q37: 0 | R37: 0 | S37: 0 | T37: 0 | U37: 0 | V37: 0 | W37: 0 | X37: 0 | Y37: 0 | Z37: 0 | AA37: 0 | AB37: 0 | AC37: 0 | AD37: 0 | AE37: 0 | AF37: 0 | AG37: 0 | AH37: 0 | AI37: 0 | AJ37: 0

Sheet Fantasma
A1: 5 | B1: 5 | C1: 5 | D1: 5 | E1: 5 | F1: 5 | G1: 5 | H1: 5 | I1: 5 | J1: 5 | K1: 5 | L1: 5 | M1: 5 | N1: 5 | O1: 5 | P1: 5 | Q1: 5 | R1: 5 | S1: 5 | T1: 5 | U1: 5 | V1: 5 | W1: 5 | X1: 5 | Y1: 5 | Z1: 5 | AA1: 5 | AB1: 5 | AC1: 5 | AD1: 5 | AE1: 5 | AF1: 5 | AG1: 5 | AH1: 5 | AI1: 5 | AJ1: 5
A2: 5 | B2: 5 | C2: 5 | D2: 5 | E2: 5 | F2: 5 | G2: 5 | H2: 5 | I2: 5 | J2: 5 | K2: 5 | L2: 5 | M2: 5 | N2: 5 | O2: 1 | P2: 1 | Q2: 1 | R2: 1 | S2: 1 | T2: 1 | U2: 1 | V2: 5 | W2: 5 | X2: 5 | Y2: 5 | Z2: 5 | AA2: 5 | AB2: 5 | AC2: 5 | AD2: 5 | AE2: 5 | AF2: 5 | AG2: 5 | AH2: 5 | AI2: 5 | AJ2: 5
A3: 5 | B3: 5 | C3: 5 | D3: 5 | E3: 5 | F3: 5 | G3: 5 | H3: 5 | I3: 5 | J3: 5 | K3: 5 | L3: 5 | M3: 1 | N3: 1 | O3: 9 | P3: 9 | Q3: 9 | R3: 9 | S3: 9 | T3: 9 | U3: 9 | V3: 1 | W3: 1 | X3: 5 | Y3: 5 | Z3: 5 | AA3: 5 | AB3: 5 | AC3: 5 | AD3: 5 | AE3: 5 | AF3: 5 | AG3: 5 | AH3: 5 | AI3: 5 | AJ3: 5
A4: 5 | B4: 5 | C4: 5 | D4: 5 | E4: 5 | F4: 5 | G4: 5 | H4: 5 | I4: 5 | J4: 5 | K4: 5 | L4: 1 | U4: 9 | V4: 9 | W4: 9 | X4: 1 | Y4: 5 | Z4: 5 | AA4: 5 | AB4: 5 | AC4: 5 | AD4: 5 | AE4: 5 | AF4: 5 | AG4: 5 | AH4: 5 | AI4: 5 | AJ4: 5
A5: 5 | B5: 5 | C5: 5 | D5: 5 | E5: 5 | F5: 5 | G5: 5 | H5: 5 | I5: 5 | J5: 5 | K5: 1 | U5: 9 | V5: 9 | W5: 9 | X5: 9 | Y5: 1 | Z5: 5 | AA5: 5 | AB5: 5 | AC5: 5 | AD5: 5 | AE5: 5 | AF5: 5 | AG5: 5 | AH5: 5 | AI5: 5 | AJ5: 5
A6: 5 | B6: 5 | C6: 5 | D6: 5 | E6: 5 | F6: 5 | G6: 5 | H6: 5 | I6: 5 | J6: 1 | W6: 9 | X6: 9 | Y6: 1 | Z6: 5 | AA6: 5 | AB6: 5 | AC6: 5 | AD6: 5 | AE6: 5 | AF6: 5 | AG6: 5 | AH6: 5 | AI6: 5 | AJ6: 5
A7: 5 | B7: 5 | C7: 5 | D7: 5 | E7: 5 | F7: 5 | G7: 5 | H7: 5 | I7: 5 | J7: 1 | W7: 9 | X7: 9 | Y7: 9 | Z7: 1 | AA7: 5 | AB7: 5 | AC7: 5 | AD7: 5 | AE7: 5 | AF7: 5 | AG7: 5 | AH7: 5 | AI7: 5 | AJ7: 5
A8: 5 | B8: 5 | C8: 5 | D8: 5 | E8: 5 | F8: 5 | G8: 5 | H8: 5 | I8: 1 | M8: 1 | Q8: 1 | X8: 9 | Y8: 9 | Z8: 1 | AA8: 5 | AB8: 5 | AC8: 5 | AD8: 5 | AE8: 5 | AF8: 5 | AG8: 5 | AH8: 5 | AI8: 5 | AJ8: 5
A9: 5 | B9: 5 | C9: 5 | D9: 5 | E9: 5 | F9: 5 | G9: 5 | H9: 5 | I9: 1 | L9: 1 | M9: 1 | Q9: 1 | R9: 1 | X9: 9 | Y9: 9 | Z9: 1 | AA9: 5 | AB9: 5 | AC9: 5 | AD9: 5 | AE9: 5 | AF9: 5 | AG9: 5 | AH9: 5 | AI9: 5 | AJ9: 5
A10: 5 | B10: 5 | C10: 5 | D10: 5 | E10: 5 | F10: 5 | G10: 5 | H10: 5 | I10: 1 | K10: 1 | L10: 1 | M10: 1 | Q10: 1 | R10: 1 | S10: 1 | X10: 9 | Y10: 9 | Z10: 9 | AA10: 1 | AB10: 5 | AC10: 5 | AD10: 5 | AE10: 5 | AF10: 5 | AG10: 5 | AH10: 5 | AI10: 5 | AJ10: 5
A11: 5 | B11: 5 | C11: 5 | D11: 5 | E11: 5 | F11: 5 | G11: 5 | H11: 5 | I11: 1 | K11: 1 | L11: 1 | M11: 1 | Q11: 1 | R11: 1 | S11: 1 | X11: 9 | Y11: 9 | Z11: 9 | AA11: 1 | AB11: 5 | AC11: 5 | AD11: 5 | AE11: 5 | AF11: 5 | AG11: 5 | AH11: 5 | AI11: 5 | AJ11: 5
A12: 5 | B12: 5 | C12: 5 | D12: 5 | E12: 5 | F12: 1 | G12: 1 | H12: 1 | I12: 1 | X12: 9 | Y12: 9 | Z12: 9 | AA12: 1 | AB12: 5 | AC12: 5 | AD12: 5 | AE12: 5 | AF12: 5 | AG12: 5 | AH12: 5 | AI12: 5 | AJ12: 5
